Workbook

Sheet Summary
A1: Virgin Golf bay model — summary
A2: Get Lucky Golf × Virgin Active, financed by RMB. 200 Golfzon bays in 130 clubs. ZAR ex VAT. Change inputs on Assumptions; nothing here is typed in.
A4: The order
A5: Capex, 200 bays landed and installed | B5: =Debt!D5+Debt!J5+Debt!P5 -> 179894000
A6: RMB facility | B6: =B5*Assumptions!$B$18 -> 161904600
A7: Equity deposit | B7: =B5-B6 -> 17989400
A8: Facility rate | B8: =Assumptions!$B$15 -> 0.12
A10: 2031, the first full year at 200 bays
B11: Low | C11: Selected case | D11: High
A12: Booked hours a bay a day | B12: ='Chain low'!F61 -> 3.549 | C12: =Chain!F61 -> 5.07 | D12: ='Chain high'!F61 -> 6.3375
A13: Revenue | B13: ='Chain low'!F68 -> 1.3772789e+08 | C13: =Chain!F68 -> 1.911827e+08 | D13: ='Chain high'!F68 -> 2.3572838e+08
A14: To Virgin Active | B14: =-'Chain low'!F69 -> 26545578 | C14: =-Chain!F69 -> 37236540 | D14: =-'Chain high'!F69 -> 46145675
A15: EBITDA | B15: ='Chain low'!F77 -> 72843581 | C15: =Chain!F77 -> 1.1159832e+08 | D15: ='Chain high'!F77 -> 1.4389393e+08
A16: EBITDA margin | B16: ='Chain low'!F78 -> 0.52889491 | C16: =Chain!F78 -> 0.58372603 | D16: ='Chain high'!F78 -> 0.61042262
A17: Debt service | B17: =-'Chain low'!F81 -> 43217741 | C17: =-Chain!F81 -> 43217741 | D17: =-'Chain high'!F81 -> 43217741
A18: Debt cover | B18: ='Chain low'!F82 -> 1.6855018 | C18: =Chain!F82 -> 2.582234 | D18: ='Chain high'!F82 -> 3.3295108
A19: Cash after debt | B19: ='Chain low'!F83 -> 29625840 | C19: =Chain!F83 -> 68380578 | D19: ='Chain high'!F83 -> 1.0067619e+08
A20: Equity needed, deposits and ramp together | B20: ='Chain low'!B89 -> 24806589 | C20: =Chain!B89 -> 8786747.5 | D20: ='Chain high'!B89 -> 6266344.4
A22: A bay at maturity, selected case
B23: Signature | C23: Play | D23: Practice
A24: Landed and installed | B24: ='Unit economics'!B6 -> 1443000 | C24: ='Unit economics'!C6 -> 841750 | D24: ='Unit economics'!D6 -> 529100
A25: Booked hours a day | B25: ='Unit economics'!B9 -> 6 | C25: ='Unit economics'!C9 -> 4.95 | D25: ='Unit economics'!D9 -> 4.5
A26: Revenue | B26: ='Unit economics'!B16 -> 1399753 | C26: ='Unit economics'!C16 -> 909095.51 | D26: ='Unit economics'!D16 -> 652528.01
A27: To Virgin Active | B27: ='Unit economics'!B29 -> 274950.6 | C27: ='Unit economics'!C29 -> 176819.1 | D27: ='Unit economics'!D29 -> 125505.6
A28: EBITDA | B28: ='Unit economics'!B24 -> 857615.93 | C28: ='Unit economics'!C24 -> 526401.74 | D28: ='Unit economics'!D24 -> 353136.81
A29: EBITDA margin | B29: ='Unit economics'!B25 -> 0.6126909 | C29: ='Unit economics'!C25 -> 0.57903899 | D29: ='Unit economics'!D25 -> 0.5411826
A30: Payback, years | B30: ='Unit economics'!B28 -> 1.6825714 | C30: ='Unit economics'!C28 -> 1.5990639 | D30: ='Unit economics'!D28 -> 1.4982862

Sheet Assumptions
A1: Virgin Golf bay model — Get Lucky Golf × Virgin Active
A2: Blue cells are inputs. Black cells are formulas. Green cells link to another sheet. Yellow is the case selector. All money in ZAR ex VAT.
A5: Case selector
A6: Utilisation multiplier in use (1.00 base, 0.70 low, 1.25 high) | B6: 1 | C6: Change this one cell to run the whole model at a different level of use. Booked hours and add-on take-up both scale with it.
A7: Low case multiplier | B7: 0.7 | C7: 70% of base use: 3.5 booked hours a bay a day at maturity.
A8: Base case multiplier | B8: 1
A9: High case multiplier | B9: 1.25 | C9: 125% of base use: 6.3 booked hours a bay a day.
A11: Money and financing
A12: ZAR per USD | B12: 18.5 | C12: Same rate as the Get Lucky investor model.
A13: SA prime lending rate | B13: 0.105 | C13: 10.5% from 28 May 2026, unchanged at the 23 July 2026 MPC. Source: SARB / debtsolutions4u.co.za prime rate tracker, August 2026.
A14: RMB margin over prime | B14: 0.015 | C14: Assumed asset-finance margin. To be replaced by the RMB term sheet.
A15: Facility rate | B15: =Assumptions!$B$13+Assumptions!$B$14 -> 0.12
A16: Interest-only months per phase | B16: 12 | C16: Capital holiday while a phase is commissioned and ramps.
A17: Amortising months per phase, after interest-only | B17: 60
A18: RMB share of landed capex | B18: 0.9 | C18: Get Lucky Golf funds the balance as an equity deposit.
A19: Landed factor on Golfzon hardware | B19: 1.3 | C19: Freight, duties, enclosure, screen, seating, installation, on top of hardware list price. Assumption; replaced by the Golfzon quote.
A20: Room shell cost carried by Get Lucky Golf, per bay | B20: 0 | C20: Opening position: Virgin Active builds the shell and power inside its refurbishments, so this is 0. If Get Lucky Golf builds, enter about R150,000. Negotiable.
A21: Shell cost per bay if Get Lucky Golf builds (for the negotiation grid) | B21: 150000
A23: The concession
A24: Virgin Active share of bay revenue | B24: 0.2 | C24: Opening position, negotiable. Applies to bay hire, memberships, leagues and the insured shot; not to sponsorship.
A25: Bookable hours a day | B25: 15 | C25: Club hours: about 05:00 to 21:00 weekdays, shorter weekends.
A26: Bookable days a year | B26: 360
A27: Bookable hours a bay a year | B27: =Assumptions!$B$25*Assumptions!$B$26 -> 5400
A28: Maximum utilisation | B28: 0.85 | C28: Cap so the high case cannot exceed a physically bookable level.
A30: Members and the add-on
A31: Virgin Active members, Southern Africa | B31: 623000 | C31: Virgin Active published figures to March 2026 (IOL Business Report, Nov 2025; Brait results).
A32: Virgin Active clubs, Southern Africa | B32: 136 | C32: Published figure, March 2026.
A33: Members a club | B33: =Assumptions!$B$31/Assumptions!$B$32 -> 4580.8824
A34: Golf add-on, R a month ex VAT, on the Virgin Active bill | B34: 299 | C34: One included off-peak hour and 20% off bookings. Included hours sit inside the utilisation figure.
A35: Add-on take-up at maturity, share of members at clubs with bays | B35: 0.015 | C35: Assumption. Scales with the utilisation multiplier.
A36: Add-on take-up ramp, year a club opens | B36: 0.4 | C36: Share of mature take-up.
A37: Add-on take-up ramp, second year | B37: 0.75
A39: Other revenue per bay
A40: Leagues, events and corporate, a bay a year at maturity | B40: 40000 | C40: Assumption.
A41: Naming partner, a bay a year | B41: 25000 | C41: Deliberately modest. Santam, RMB or a beverage brand could take chain naming at a multiple.
A42: Get Lucky insured shot: stake | B42: 50 | C42: R50 for a swing at R25,000, as on course.
A43: Insured shots taken per booked bay-hour | B43: 0.625 | C43: 2.5 players in a bay-hour, one in four takes a shot.
A44: Premium ceded to Santam, share of stake | B44: 0.24 | C44: Same 24% as the on-course product in the investor model.
A45: Insured shot revenue per booked hour, net of premium | B45: =Assumptions!$B$42*Assumptions!$B$43*(1-Assumptions!$B$44) -> 23.75
A47: Operating costs
...

Sheet Unit economics
A1: A bay at maturity, at the multiplier in use
A2: Per bay, per year, ZAR ex VAT. Membership, people and central are allocated evenly across the 200 bays.
B4: Signature | C4: Play | D4: Practice
A5: Hardware, ZAR | B5: =Assumptions!$B$63*Assumptions!$B$12 -> 1110000 | C5: =Assumptions!$B$64*Assumptions!$B$12 -> 647500 | D5: =Assumptions!$B$65*Assumptions!$B$12 -> 407000
A6: Landed and installed, plus any shell cost carried | B6: =B5*Assumptions!$B$19+Assumptions!$B$20 -> 1443000 | C6: =C5*Assumptions!$B$19+Assumptions!$B$20 -> 841750 | D6: =D5*Assumptions!$B$19+Assumptions!$B$20 -> 529100
A7: Utilisation in use | B7: =MIN(Assumptions!$C$63*Assumptions!$B$6,Assumptions!$B$28) -> 0.4 | C7: =MIN(Assumptions!$C$64*Assumptions!$B$6,Assumptions!$B$28) -> 0.33 | D7: =MIN(Assumptions!$C$65*Assumptions!$B$6,Assumptions!$B$28) -> 0.3
A8: Booked hours a year | B8: =Assumptions!$B$27*B7 -> 2160 | C8: =Assumptions!$B$27*C7 -> 1782 | D8: =Assumptions!$B$27*D7 -> 1620
A9: Booked hours a day | B9: =B8/Assumptions!$B$26 -> 6 | C9: =C8/Assumptions!$B$26 -> 4.95 | D9: =D8/Assumptions!$B$26 -> 4.5
A10: Blended yield per booked hour | B10: =Assumptions!$D$63 -> 520 | C10: =Assumptions!$D$64 -> 360 | D10: =Assumptions!$D$65 -> 240
A11: Bay hire | B11: =B8*B10 -> 1123200 | C11: =C8*C10 -> 641520 | D11: =D8*D10 -> 388800
A12: Golf add-on, allocated per bay | B12: =(Assumptions!$G$69+Assumptions!$G$70+Assumptions!$G$71)*Assumptions!$B$33*Assumptions!$B$35*Assumptions!$B$6*Assumptions!$B$34*12/SUM(Assumptions!$E$63:$E$65) -> 160253.01 | C12: =(Assumptions!$G$69+Assumptions!$G$70+Assumptions!$G$71)*Assumptions!$B$33*Assumptions!$B$35*Assumptions!$B$6*Assumptions!$B$34*12/SUM(Assumptions!$E$63:$E$65) -> 160253.01 | D12: =(Assumptions!$G$69+Assumptions!$G$70+Assumptions!$G$71)*Assumptions!$B$33*Assumptions!$B$35*Assumptions!$B$6*Assumptions!$B$34*12/SUM(Assumptions!$E$63:$E$65) -> 160253.01
A13: Leagues, events, corporate | B13: =Assumptions!$B$40 -> 40000 | C13: =Assumptions!$B$40 -> 40000 | D13: =Assumptions!$B$40 -> 40000
A14: Get Lucky insured shot, net of premium | B14: =B8*Assumptions!$B$45 -> 51300 | C14: =C8*Assumptions!$B$45 -> 42322.5 | D14: =D8*Assumptions!$B$45 -> 38475
A15: Naming partner | B15: =Assumptions!$B$41 -> 25000 | C15: =Assumptions!$B$41 -> 25000 | D15: =Assumptions!$B$41 -> 25000
A16: Revenue | B16: =SUM(B11:B15) -> 1399753 | C16: =SUM(C11:C15) -> 909095.51 | D16: =SUM(D11:D15) -> 652528.01
A17: Virgin Active concession | B17: =-(B16-B15)*Assumptions!$B$24 -> -274950.6 | C17: =-(C16-C15)*Assumptions!$B$24 -> -176819.1 | D17: =-(D16-D15)*Assumptions!$B$24 -> -125505.6
A18: Card and booking fees | B18: =-(B16-B15)*Assumptions!$B$48 -> -34368.825 | C18: =-(C16-C15)*Assumptions!$B$48 -> -22102.388 | D18: =-(D16-D15)*Assumptions!$B$48 -> -15688.2
A19: Marketing | B19: =-B16*Assumptions!$B$49 -> -69987.65 | C19: =-C16*Assumptions!$B$49 -> -45454.775 | D19: =-D16*Assumptions!$B$49 -> -32626.4
A20: Golfzon service and software | B20: =-B5*Assumptions!$B$51 -> -44400 | C20: =-C5*Assumptions!$B$51 -> -25900 | D20: =-D5*Assumptions!$B$51 -> -16280
A21: Consumables and maintenance | B21: =-Assumptions!$B$52 -> -24000 | C21: =-Assumptions!$B$52 -> -24000 | D21: =-Assumptions!$B$52 -> -24000
A22: Asset insurance | B22: =-B6*Assumptions!$B$50 -> -14430 | C22: =-C6*Assumptions!$B$50 -> -8417.5 | D22: =-D6*Assumptions!$B$50 -> -5291
A23: People and central, allocated | B23: =-Assumptions!$B$53 -> -80000 | C23: =-Assumptions!$B$53 -> -80000 | D23: =-Assumptions!$B$53 -> -80000
A24: EBITDA | B24: =SUM(B16:B23) -> 857615.93 | C24: =SUM(C16:C23) -> 526401.74 | D24: =SUM(D16:D23) -> 353136.81
A25: EBITDA margin | B25: =IF(B16=0,0,B24/B16) -> 0.6126909 | C25: =IF(C16=0,0,C24/C16) -> 0.57903899 | D25: =IF(D16=0,0,D24/D16) -> 0.5411826
A26: RMB instalments, full amortising year | B26: =-(B6*Assumptions!$B$18)*(Assumptions!$B$15/12)/(1-(1+Assumptions!$B$15/12)^-Assumptions!$B$17)*12 -> -346666.37 | C26: =-(C6*Assumptions!$B$18)*(Assumptions!$B$15/12)/(1-(1+Assumptions!$B$15/12)^-Assumptions!$B$17)*12 -> -202222.05 | D26: =-(D6*Assumptions!$B$18)*(Assumptions!$B$15/12)/(1-(1+Assumptions!$B$15/12)^-Assumptions!$B$17)*12 -> -127111
A27: Cash after debt | B27: =B24+B26 -> 510949.56 | C27: =C24+C26 -> 324179.69 | D27: =D24+D26 -> 226025.8
A28: Payback on capex from EBITDA, years | B28: =IF(B24<=0,"n/a",B6/B24) -> 1.6825714 | C28: =IF(C24<=0,"n/a",C6/C24) -> 1.5990639 | D28: =IF(D24<=0,"n/a",D6/D24) -> 1.4982862
A29: Memo: to Virgin Active, a bay a year | B29: =-B17 -> 274950.6 | C29: =-C17 -> 176819.1 | D29: =-D17 -> 125505.6

Sheet Debt
A1: RMB facility, monthly, by phase
A2: Each phase is drawn in January of its commissioning year, interest-only for the holiday, then amortised over the term. Capex per phase includes any shell cost carried.
A4: Phase | C4: Phase 1 | I4: Phase 2 | O4: Phase 3
C5: Capex | D5: =Assumptions!$D$69*(Assumptions!$B$63*Assumptions!$B$12*Assumptions!$B$19+Assumptions!$B$20)+Assumptions!$E$69*(Assumptions!$B$64*Assumptions!$B$12*Assumptions!$B$19+Assumptions!$B$20)+Assumptions!$F$69*(Assumptions!$B$65*Assumptions!$B$12*Assumptions!$B$19+Assumptions!$B$20) -> 57720000 | I5: Capex | J5: =Assumptions!$D$70*(Assumptions!$B$63*Assumptions!$B$12*Assumptions!$B$19+Assumptions!$B$20)+Assumptions!$E$70*(Assumptions!$B$64*Assumptions!$B$12*Assumptions!$B$19+Assumptions!$B$20)+Assumptions!$F$70*(Assumptions!$B$65*Assumptions!$B$12*Assumptions!$B$19+Assumptions!$B$20) -> 84175000 | O5: Capex | P5: =Assumptions!$D$71*(Assumptions!$B$63*Assumptions!$B$12*Assumptions!$B$19+Assumptions!$B$20)+Assumptions!$E$71*(Assumptions!$B$64*Assumptions!$B$12*Assumptions!$B$19+Assumptions!$B$20)+Assumptions!$F$71*(Assumptions!$B$65*Assumptions!$B$12*Assumptions!$B$19+Assumptions!$B$20) -> 37999000
C6: Drawn | D6: =D5*Assumptions!$B$18 -> 51948000 | I6: Drawn | J6: =J5*Assumptions!$B$18 -> 75757500 | O6: Drawn | P6: =P5*Assumptions!$B$18 -> 34199100
C7: Draw month # | D7: =(Assumptions!$B$69-2027)*12+1 -> 1 | I7: Draw month # | J7: =(Assumptions!$B$70-2027)*12+1 -> 13 | O7: Draw month # | P7: =(Assumptions!$B$71-2027)*12+1 -> 25
C8: Instalment | D8: =D6*(Assumptions!$B$15/12)/(1-(1+Assumptions!$B$15/12)^-Assumptions!$B$17) -> 1155554.6 | I8: Instalment | J8: =J6*(Assumptions!$B$15/12)/(1-(1+Assumptions!$B$15/12)^-Assumptions!$B$17) -> 1685183.7 | O8: Instalment | P8: =P6*(Assumptions!$B$15/12)/(1-(1+Assumptions!$B$15/12)^-Assumptions!$B$17) -> 760740.09
A10: Month # | B10: Year | C10: Opening | D10: Interest | E10: Principal | F10: Closing | I10: Opening | J10: Interest | K10: Principal | L10: Closing | O10: Opening | P10: Interest | Q10: Principal | R10: Closing
A11: 1 | B11: =2027+INT((A11-1)/12) -> 2027 | C11: =IF(A11=$D$7,$D$6,0) -> 51948000 | D11: =C11*Assumptions!$B$15/12 -> 519480 | E11: =IF(A11-$D$7+1>Assumptions!$B$16,MIN(MAX($D$8-D11,0),C11),0) -> 0 | F11: =C11-E11 -> 51948000 | I11: =IF(A11=$J$7,$J$6,0) -> 0 | J11: =I11*Assumptions!$B$15/12 -> 0 | K11: =IF(A11-$J$7+1>Assumptions!$B$16,MIN(MAX($J$8-J11,0),I11),0) -> 0 | L11: =I11-K11 -> 0 | O11: =IF(A11=$P$7,$P$6,0) -> 0 | P11: =O11*Assumptions!$B$15/12 -> 0 | Q11: =IF(A11-$P$7+1>Assumptions!$B$16,MIN(MAX($P$8-P11,0),O11),0) -> 0 | R11: =O11-Q11 -> 0
A12: 2 | B12: =2027+INT((A12-1)/12) -> 2027 | C12: =IF(A12=$D$7,$D$6,IF(A12>$D$7,F11,0)) -> 51948000 | D12: =C12*Assumptions!$B$15/12 -> 519480 | E12: =IF(A12-$D$7+1>Assumptions!$B$16,MIN(MAX($D$8-D12,0),C12),0) -> 0 | F12: =C12-E12 -> 51948000 | I12: =IF(A12=$J$7,$J$6,IF(A12>$J$7,L11,0)) -> 0 | J12: =I12*Assumptions!$B$15/12 -> 0 | K12: =IF(A12-$J$7+1>Assumptions!$B$16,MIN(MAX($J$8-J12,0),I12),0) -> 0 | L12: =I12-K12 -> 0 | O12: =IF(A12=$P$7,$P$6,IF(A12>$P$7,R11,0)) -> 0 | P12: =O12*Assumptions!$B$15/12 -> 0 | Q12: =IF(A12-$P$7+1>Assumptions!$B$16,MIN(MAX($P$8-P12,0),O12),0) -> 0 | R12: =O12-Q12 -> 0
A13: 3 | B13: =2027+INT((A13-1)/12) -> 2027 | C13: =IF(A13=$D$7,$D$6,IF(A13>$D$7,F12,0)) -> 51948000 | D13: =C13*Assumptions!$B$15/12 -> 519480 | E13: =IF(A13-$D$7+1>Assumptions!$B$16,MIN(MAX($D$8-D13,0),C13),0) -> 0 | F13: =C13-E13 -> 51948000 | I13: =IF(A13=$J$7,$J$6,IF(A13>$J$7,L12,0)) -> 0 | J13: =I13*Assumptions!$B$15/12 -> 0 | K13: =IF(A13-$J$7+1>Assumptions!$B$16,MIN(MAX($J$8-J13,0),I13),0) -> 0 | L13: =I13-K13 -> 0 | O13: =IF(A13=$P$7,$P$6,IF(A13>$P$7,R12,0)) -> 0 | P13: =O13*Assumptions!$B$15/12 -> 0 | Q13: =IF(A13-$P$7+1>Assumptions!$B$16,MIN(MAX($P$8-P13,0),O13),0) -> 0 | R13: =O13-Q13 -> 0
A14: 4 | B14: =2027+INT((A14-1)/12) -> 2027 | C14: =IF(A14=$D$7,$D$6,IF(A14>$D$7,F13,0)) -> 51948000 | D14: =C14*Assumptions!$B$15/12 -> 519480 | E14: =IF(A14-$D$7+1>Assumptions!$B$16,MIN(MAX($D$8-D14,0),C14),0) -> 0 | F14: =C14-E14 -> 51948000 | I14: =IF(A14=$J$7,$J$6,IF(A14>$J$7,L13,0)) -> 0 | J14: =I14*Assumptions!$B$15/12 -> 0 | K14: =IF(A14-$J$7+1>Assumptions!$B$16,MIN(MAX($J$8-J14,0),I14),0) -> 0 | L14: =I14-K14 -> 0 | O14: =IF(A14=$P$7,$P$6,IF(A14>$P$7,R13,0)) -> 0 | P14: =O14*Assumptions!$B$15/12 -> 0 | Q14: =IF(A14-$P$7+1>Assumptions!$B$16,MIN(MAX($P$8-P14,0),O14),0) -> 0 | R14: =O14-Q14 -> 0
A15: 5 | B15: =2027+INT((A15-1)/12) -> 2027 | C15: =IF(A15=$D$7,$D$6,IF(A15>$D$7,F14,0)) -> 51948000 | D15: =C15*Assumptions!$B$15/12 -> 519480 | E15: =IF(A15-$D$7+1>Assumptions!$B$16,MIN(MAX($D$8-D15,0),C15),0) -> 0 | F15: =C15-E15 -> 51948000 | I15: =IF(A15=$J$7,$J$6,IF(A15>$J$7,L14,0)) -> 0 | J15: =I15*Assumptions!$B$15/12 -> 0 | K15: =IF(A15-$J$7+1>Assumptions!$B$16,MIN(MAX($J$8-J15,0),I15),0) -> 0 | L15: =I15-K15 -> 0 | O15: =IF(A15=$P$7,$P$6,IF(A15>$P$7,R14,0)) -> 0 | P15: =O15*Assumptions!$B$15/12 -> 0 | Q15: =IF(A15-$P$7+1>Assumptions!$B$16,MIN(MAX($P$8-P15,0),O15),0) -> 0 | R15: =O15-Q15 -> 0
A16: 6 | B16: =2027+INT((A16-1)/12) -> 2027 | C16: =IF(A16=$D$7,$D$6,IF(A16>$D$7,F15,0)) -> 51948000 | D16: =C16*Assumptions!$B$15/12 -> 519480 | E16: =IF(A16-$D$7+1>Assumptions!$B$16,MIN(MAX($D$8-D16,0),C16),0) -> 0 | F16: =C16-E16 -> 51948000 | I16: =IF(A16=$J$7,$J$6,IF(A16>$J$7,L15,0)) -> 0 | J16: =I16*Assumptions!$B$15/12 -> 0 | K16: =IF(A16-$J$7+1>Assumptions!$B$16,MIN(MAX($J$8-J16,0),I16),0) -> 0 | L16: =I16-K16 -> 0 | O16: =IF(A16=$P$7,$P$6,IF(A16>$P$7,R15,0)) -> 0 | P16: =O16*Assumptions!$B$15/12 -> 0 | Q16: =IF(A16-$P$7+1>Assumptions!$B$16,MIN(MAX($P$8-P16,0),O16),0) -> 0 | R16: =O16-Q16 -> 0
A17: 7 | B17: =2027+INT((A17-1)/12) -> 2027 | C17: =IF(A17=$D$7,$D$6,IF(A17>$D$7,F16,0)) -> 51948000 | D17: =C17*Assumptions!$B$15/12 -> 519480 | E17: =IF(A17-$D$7+1>Assumptions!$B$16,MIN(MAX($D$8-D17,0),C17),0) -> 0 | F17: =C17-E17 -> 51948000 | I17: =IF(A17=$J$7,$J$6,IF(A17>$J$7,L16,0)) -> 0 | J17: =I17*Assumptions!$B$15/12 -> 0 | K17: =IF(A17-$J$7+1>Assumptions!$B$16,MIN(MAX($J$8-J17,0),I17),0) -> 0 | L17: =I17-K17 -> 0 | O17: =IF(A17=$P$7,$P$6,IF(A17>$P$7,R16,0)) -> 0 | P17: =O17*Assumptions!$B$15/12 -> 0 | Q17: =IF(A17-$P$7+1>Assumptions!$B$16,MIN(MAX($P$8-P17,0),O17),0) -> 0 | R17: =O17-Q17 -> 0
A18: 8 | B18: =2027+INT((A18-1)/12) -> 2027 | C18: =IF(A18=$D$7,$D$6,IF(A18>$D$7,F17,0)) -> 51948000 | D18: =C18*Assumptions!$B$15/12 -> 519480 | E18: =IF(A18-$D$7+1>Assumptions!$B$16,MIN(MAX($D$8-D18,0),C18),0) -> 0 | F18: =C18-E18 -> 51948000 | I18: =IF(A18=$J$7,$J$6,IF(A18>$J$7,L17,0)) -> 0 | J18: =I18*Assumptions!$B$15/12 -> 0 | K18: =IF(A18-$J$7+1>Assumptions!$B$16,MIN(MAX($J$8-J18,0),I18),0) -> 0 | L18: =I18-K18 -> 0 | O18: =IF(A18=$P$7,$P$6,IF(A18>$P$7,R17,0)) -> 0 | P18: =O18*Assumptions!$B$15/12 -> 0 | Q18: =IF(A18-$P$7+1>Assumptions!$B$16,MIN(MAX($P$8-P18,0),O18),0) -> 0 | R18: =O18-Q18 -> 0
A19: 9 | B19: =2027+INT((A19-1)/12) -> 2027 | C19: =IF(A19=$D$7,$D$6,IF(A19>$D$7,F18,0)) -> 51948000 | D19: =C19*Assumptions!$B$15/12 -> 519480 | E19: =IF(A19-$D$7+1>Assumptions!$B$16,MIN(MAX($D$8-D19,0),C19),0) -> 0 | F19: =C19-E19 -> 51948000 | I19: =IF(A19=$J$7,$J$6,IF(A19>$J$7,L18,0)) -> 0 | J19: =I19*Assumptions!$B$15/12 -> 0 | K19: =IF(A19-$J$7+1>Assumptions!$B$16,MIN(MAX($J$8-J19,0),I19),0) -> 0 | L19: =I19-K19 -> 0 | O19: =IF(A19=$P$7,$P$6,IF(A19>$P$7,R18,0)) -> 0 | P19: =O19*Assumptions!$B$15/12 -> 0 | Q19: =IF(A19-$P$7+1>Assumptions!$B$16,MIN(MAX($P$8-P19,0),O19),0) -> 0 | R19: =O19-Q19 -> 0
A20: 10 | B20: =2027+INT((A20-1)/12) -> 2027 | C20: =IF(A20=$D$7,$D$6,IF(A20>$D$7,F19,0)) -> 51948000 | D20: =C20*Assumptions!$B$15/12 -> 519480 | E20: =IF(A20-$D$7+1>Assumptions!$B$16,MIN(MAX($D$8-D20,0),C20),0) -> 0 | F20: =C20-E20 -> 51948000 | I20: =IF(A20=$J$7,$J$6,IF(A20>$J$7,L19,0)) -> 0 | J20: =I20*Assumptions!$B$15/12 -> 0 | K20: =IF(A20-$J$7+1>Assumptions!$B$16,MIN(MAX($J$8-J20,0),I20),0) -> 0 | L20: =I20-K20 -> 0 | O20: =IF(A20=$P$7,$P$6,IF(A20>$P$7,R19,0)) -> 0 | P20: =O20*Assumptions!$B$15/12 -> 0 | Q20: =IF(A20-$P$7+1>Assumptions!$B$16,MIN(MAX($P$8-P20,0),O20),0) -> 0 | R20: =O20-Q20 -> 0
A21: 11 | B21: =2027+INT((A21-1)/12) -> 2027 | C21: =IF(A21=$D$7,$D$6,IF(A21>$D$7,F20,0)) -> 51948000 | D21: =C21*Assumptions!$B$15/12 -> 519480 | E21: =IF(A21-$D$7+1>Assumptions!$B$16,MIN(MAX($D$8-D21,0),C21),0) -> 0 | F21: =C21-E21 -> 51948000 | I21: =IF(A21=$J$7,$J$6,IF(A21>$J$7,L20,0)) -> 0 | J21: =I21*Assumptions!$B$15/12 -> 0 | K21: =IF(A21-$J$7+1>Assumptions!$B$16,MIN(MAX($J$8-J21,0),I21),0) -> 0 | L21: =I21-K21 -> 0 | O21: =IF(A21=$P$7,$P$6,IF(A21>$P$7,R20,0)) -> 0 | P21: =O21*Assumptions!$B$15/12 -> 0 | Q21: =IF(A21-$P$7+1>Assumptions!$B$16,MIN(MAX($P$8-P21,0),O21),0) -> 0 | R21: =O21-Q21 -> 0
A22: 12 | B22: =2027+INT((A22-1)/12) -> 2027 | C22: =IF(A22=$D$7,$D$6,IF(A22>$D$7,F21,0)) -> 51948000 | D22: =C22*Assumptions!$B$15/12 -> 519480 | E22: =IF(A22-$D$7+1>Assumptions!$B$16,MIN(MAX($D$8-D22,0),C22),0) -> 0 | F22: =C22-E22 -> 51948000 | I22: =IF(A22=$J$7,$J$6,IF(A22>$J$7,L21,0)) -> 0 | J22: =I22*Assumptions!$B$15/12 -> 0 | K22: =IF(A22-$J$7+1>Assumptions!$B$16,MIN(MAX($J$8-J22,0),I22),0) -> 0 | L22: =I22-K22 -> 0 | O22: =IF(A22=$P$7,$P$6,IF(A22>$P$7,R21,0)) -> 0 | P22: =O22*Assumptions!$B$15/12 -> 0 | Q22: =IF(A22-$P$7+1>Assumptions!$B$16,MIN(MAX($P$8-P22,0),O22),0) -> 0 | R22: =O22-Q22 -> 0
A23: 13 | B23: =2027+INT((A23-1)/12) -> 2028 | C23: =IF(A23=$D$7,$D$6,IF(A23>$D$7,F22,0)) -> 51948000 | D23: =C23*Assumptions!$B$15/12 -> 519480 | E23: =IF(A23-$D$7+1>Assumptions!$B$16,MIN(MAX($D$8-D23,0),C23),0) -> 636074.57 | F23: =C23-E23 -> 51311925 | I23: =IF(A23=$J$7,$J$6,IF(A23>$J$7,L22,0)) -> 75757500 | J23: =I23*Assumptions!$B$15/12 -> 757575 | K23: =IF(A23-$J$7+1>Assumptions!$B$16,MIN(MAX($J$8-J23,0),I23),0) -> 0 | L23: =I23-K23 -> 75757500 | O23: =IF(A23=$P$7,$P$6,IF(A23>$P$7,R22,0)) -> 0 | P23: =O23*Assumptions!$B$15/12 -> 0 | Q23: =IF(A23-$P$7+1>Assumptions!$B$16,MIN(MAX($P$8-P23,0),O23),0) -> 0 | R23: =O23-Q23 -> 0
... A82: 72 | B82: =2027+INT((A82-1)/12) -> 2032 | C82: =IF(A82=$D$7,$D$6,IF(A82>$D$7,F81,0)) -> 1144113.4 | D82: =C82*Assumptions!$B$15/12 -> 11441.134 | E82: =IF(A82-$D$7+1>Assumptions!$B$16,MIN(MAX($D$8-D82,0),C82),0) -> 1144113.4 | F82: =C82-E82 -> 6.8219379e-08 | I82: =IF(A82=$J$7,$J$6,IF(A82>$J$7,L81,0)) -> 20447582 | J82: =I82*Assumptions!$B$15/12 -> 204475.82 | K82: =IF(A82-$J$7+1>Assumptions!$B$16,MIN(MAX($J$8-J82,0),I82),0) -> 1480707.9 | L82: =I82-K82 -> 18966874 | O82: =IF(A82=$P$7,$P$6,IF(A82>$P$7,R81,0)) -> 16753897 | P82: =O82*Assumptions!$B$15/12 -> 167538.97 | Q82: =IF(A82-$P$7+1>Assumptions!$B$16,MIN(MAX($P$8-P82,0),O82),0) -> 593201.12 | R82: =O82-Q82 -> 16160696
A85: Annual
A86: Year | B86: 2027 | C86: 2028 | D86: 2029 | E86: 2030 | F86: 2031 | G86: 2032
A87: Phase 1 interest | B87: =SUMIF($B$11:$B$82,2027,D$11:D$82) -> 6233760 | C87: =SUMIF($B$11:$B$82,2028,D$11:D$82) -> 5799637.2 | D87: =SUMIF($B$11:$B$82,2029,D$11:D$82) -> 4776537.4 | E87: =SUMIF($B$11:$B$82,2030,D$11:D$82) -> 3623683 | F87: =SUMIF($B$11:$B$82,2031,D$11:D$82) -> 2324617.8 | G87: =SUMIF($B$11:$B$82,2032,D$11:D$82) -> 860798.63
A88: Phase 1 principal | B88: =SUMIF($B$11:$B$82,2027,E$11:E$82) -> 0 | C88: =SUMIF($B$11:$B$82,2028,E$11:E$82) -> 8067017.6 | D88: =SUMIF($B$11:$B$82,2029,E$11:E$82) -> 9090117.4 | E88: =SUMIF($B$11:$B$82,2030,E$11:E$82) -> 10242972 | F88: =SUMIF($B$11:$B$82,2031,E$11:E$82) -> 11542037 | G88: =SUMIF($B$11:$B$82,2032,E$11:E$82) -> 13005856
A89: Phase 2 interest | B89: =SUMIF($B$11:$B$82,2027,J$11:J$82) -> 0 | C89: =SUMIF($B$11:$B$82,2028,J$11:J$82) -> 9090900 | D89: =SUMIF($B$11:$B$82,2029,J$11:J$82) -> 8457804.2 | E89: =SUMIF($B$11:$B$82,2030,J$11:J$82) -> 6965783.8 | F89: =SUMIF($B$11:$B$82,2031,J$11:J$82) -> 5284537.7 | G89: =SUMIF($B$11:$B$82,2032,J$11:J$82) -> 3390067.7
A90: Phase 2 principal | B90: =SUMIF($B$11:$B$82,2027,K$11:K$82) -> 0 | C90: =SUMIF($B$11:$B$82,2028,K$11:K$82) -> 0 | D90: =SUMIF($B$11:$B$82,2029,K$11:K$82) -> 11764401 | E90: =SUMIF($B$11:$B$82,2030,K$11:K$82) -> 13256421 | F90: =SUMIF($B$11:$B$82,2031,K$11:K$82) -> 14937667 | G90: =SUMIF($B$11:$B$82,2032,K$11:K$82) -> 16832137
A91: Phase 3 interest | B91: =SUMIF($B$11:$B$82,2027,P$11:P$82) -> 0 | C91: =SUMIF($B$11:$B$82,2028,P$11:P$82) -> 0 | D91: =SUMIF($B$11:$B$82,2029,P$11:P$82) -> 4103892 | E91: =SUMIF($B$11:$B$82,2030,P$11:P$82) -> 3818094.5 | F91: =SUMIF($B$11:$B$82,2031,P$11:P$82) -> 3144553.8 | G91: =SUMIF($B$11:$B$82,2032,P$11:P$82) -> 2385591.3
A92: Phase 3 principal | B92: =SUMIF($B$11:$B$82,2027,Q$11:Q$82) -> 0 | C92: =SUMIF($B$11:$B$82,2028,Q$11:Q$82) -> 0 | D92: =SUMIF($B$11:$B$82,2029,Q$11:Q$82) -> 0 | E92: =SUMIF($B$11:$B$82,2030,Q$11:Q$82) -> 5310786.6 | F92: =SUMIF($B$11:$B$82,2031,Q$11:Q$82) -> 5984327.3 | G92: =SUMIF($B$11:$B$82,2032,Q$11:Q$82) -> 6743289.8
A93: Total interest | B93: =B87+B89+B91 -> 6233760 | C93: =C87+C89+C91 -> 14890537 | D93: =D87+D89+D91 -> 17338234 | E93: =E87+E89+E91 -> 14407561 | F93: =F87+F89+F91 -> 10753709 | G93: =G87+G89+G91 -> 6636457.6
A94: Total principal | B94: =B88+B90+B92 -> 0 | C94: =C88+C90+C92 -> 8067017.6 | D94: =D88+D90+D92 -> 20854518 | E94: =E88+E90+E92 -> 28810180 | F94: =F88+F90+F92 -> 32464031 | G94: =G88+G90+G92 -> 36581283
A95: Total debt service | B95: =B93+B94 -> 6233760 | C95: =C93+C94 -> 22957555 | D95: =D93+D94 -> 38192752 | E95: =E93+E94 -> 43217741 | F95: =F93+F94 -> 43217741 | G95: =G93+G94 -> 43217741
A96: Closing balance | B96: =IF(2027>=Assumptions!$B$69,Debt!$D$6,0)+IF(2027>=Assumptions!$B$70,Debt!$J$6,0)+IF(2027>=Assumptions!$B$71,Debt!$P$6,0)-SUMIF($B$11:$B$82,"<="&2027,$A$11:$A$82)*0-(SUMIF($B$11:$B$82,"<="&2027,E$11:E$82)+SUMIF($B$11:$B$82,"<="&2027,K$11:K$82)+SUMIF($B$11:$B$82,"<="&2027,Q$11:Q$82)) -> 51948000 | C96: =IF(2028>=Assumptions!$B$69,Debt!$D$6,0)+IF(2028>=Assumptions!$B$70,Debt!$J$6,0)+IF(2028>=Assumptions!$B$71,Debt!$P$6,0)-SUMIF($B$11:$B$82,"<="&2028,$A$11:$A$82)*0-(SUMIF($B$11:$B$82,"<="&2028,E$11:E$82)+SUMIF($B$11:$B$82,"<="&2028,K$11:K$82)+SUMIF($B$11:$B$82,"<="&2028,Q$11:Q$82)) -> 1.1963848e+08 | D96: =IF(2029>=Assumptions!$B$69,Debt!$D$6,0)+IF(2029>=Assumptions!$B$70,Debt!$J$6,0)+IF(2029>=Assumptions!$B$71,Debt!$P$6,0)-SUMIF($B$11:$B$82,"<="&2029,$A$11:$A$82)*0-(SUMIF($B$11:$B$82,"<="&2029,E$11:E$82)+SUMIF($B$11:$B$82,"<="&2029,K$11:K$82)+SUMIF($B$11:$B$82,"<="&2029,Q$11:Q$82)) -> 1.3298306e+08 | E96: =IF(2030>=Assumptions!$B$69,Debt!$D$6,0)+IF(2030>=Assumptions!$B$70,Debt!$J$6,0)+IF(2030>=Assumptions!$B$71,Debt!$P$6,0)-SUMIF($B$11:$B$82,"<="&2030,$A$11:$A$82)*0-(SUMIF($B$11:$B$82,"<="&2030,E$11:E$82)+SUMIF($B$11:$B$82,"<="&2030,K$11:K$82)+SUMIF($B$11:$B$82,"<="&2030,Q$11:Q$82)) -> 1.0417288e+08 | F96: =IF(2031>=Assumptions!$B$69,Debt!$D$6,0)+IF(2031>=Assumptions!$B$70,Debt!$J$6,0)+IF(2031>=Assumptions!$B$71,Debt!$P$6,0)-SUMIF($B$11:$B$82,"<="&2031,$A$11:$A$82)*0-(SUMIF($B$11:$B$82,"<="&2031,E$11:E$82)+SUMIF($B$11:$B$82,"<="&2031,K$11:K$82)+SUMIF($B$11:$B$82,"<="&2031,Q$11:Q$82)) -> 71708853 | G96: =IF(2032>=Assumptions!$B$69,Debt!$D$6,0)+IF(2032>=Assumptions!$B$70,Debt!$J$6,0)+IF(2032>=Assumptions!$B$71,Debt!$P$6,0)-SUMIF($B$11:$B$82,"<="&2032,$A$11:$A$82)*0-(SUMIF($B$11:$B$82,"<="&2032,E$11:E$82)+SUMIF($B$11:$B$82,"<="&2032,K$11:K$82)+SUMIF($B$11:$B$82,"<="&2032,Q$11:Q$82)) -> 35127570

Sheet Chain
A1: The chain, 2027 to 2032 — at the multiplier selected on Assumptions
A2: Utilisation multiplier | B2: =Assumptions!$B$6 -> 1
A4: Year | B4: 2027 | C4: 2028 | D4: 2029 | E4: 2030 | F4: 2031 | G4: 2032
A6: Phase 1
A7: Bay age, years | B7: =2027-Assumptions!$B$69 -> 0 | C7: =2028-Assumptions!$B$69 -> 1 | D7: =2029-Assumptions!$B$69 -> 2 | E7: =2030-Assumptions!$B$69 -> 3 | F7: =2031-Assumptions!$B$69 -> 4 | G7: =2032-Assumptions!$B$69 -> 5
A8: Share of year live | B8: =IF(B7<0,0,IF(B7=0,Assumptions!$C$69,1)) -> 0.5 | C8: =IF(C7<0,0,IF(C7=0,Assumptions!$C$69,1)) -> 1 | D8: =IF(D7<0,0,IF(D7=0,Assumptions!$C$69,1)) -> 1 | E8: =IF(E7<0,0,IF(E7=0,Assumptions!$C$69,1)) -> 1 | F8: =IF(F7<0,0,IF(F7=0,Assumptions!$C$69,1)) -> 1 | G8: =IF(G7<0,0,IF(G7=0,Assumptions!$C$69,1)) -> 1
A9: Use factor (live × ramp) | B9: =B8*IF(B7=0,Assumptions!$B$56,IF(B7=1,Assumptions!$B$57,1)) -> 0.275 | C9: =C8*IF(C7=0,Assumptions!$B$56,IF(C7=1,Assumptions!$B$57,1)) -> 0.8 | D9: =D8*IF(D7=0,Assumptions!$B$56,IF(D7=1,Assumptions!$B$57,1)) -> 1 | E9: =E8*IF(E7=0,Assumptions!$B$56,IF(E7=1,Assumptions!$B$57,1)) -> 1 | F9: =F8*IF(F7=0,Assumptions!$B$56,IF(F7=1,Assumptions!$B$57,1)) -> 1 | G9: =G8*IF(G7=0,Assumptions!$B$56,IF(G7=1,Assumptions!$B$57,1)) -> 1
A10: Capex in year | B10: =IF(B7=0,Debt!$D$5,0) -> 57720000 | C10: =IF(C7=0,Debt!$D$5,0) -> 0 | D10: =IF(D7=0,Debt!$D$5,0) -> 0 | E10: =IF(E7=0,Debt!$D$5,0) -> 0 | F10: =IF(F7=0,Debt!$D$5,0) -> 0 | G10: =IF(G7=0,Debt!$D$5,0) -> 0
A11: Bays live | B11: =IF(B7>=0,SUM(Assumptions!$D$69:$F$69),0) -> 40 | C11: =IF(C7>=0,SUM(Assumptions!$D$69:$F$69),0) -> 40 | D11: =IF(D7>=0,SUM(Assumptions!$D$69:$F$69),0) -> 40 | E11: =IF(E7>=0,SUM(Assumptions!$D$69:$F$69),0) -> 40 | F11: =IF(F7>=0,SUM(Assumptions!$D$69:$F$69),0) -> 40 | G11: =IF(G7>=0,SUM(Assumptions!$D$69:$F$69),0) -> 40
A12: Clubs live | B12: =IF(B7>=0,Assumptions!$G$69,0) -> 20 | C12: =IF(C7>=0,Assumptions!$G$69,0) -> 20 | D12: =IF(D7>=0,Assumptions!$G$69,0) -> 20 | E12: =IF(E7>=0,Assumptions!$G$69,0) -> 20 | F12: =IF(F7>=0,Assumptions!$G$69,0) -> 20 | G12: =IF(G7>=0,Assumptions!$G$69,0) -> 20
A13: Booked hours | B13: =(Assumptions!$D$69*MIN(Assumptions!$C$63*$B$2,Assumptions!$B$28)+Assumptions!$E$69*MIN(Assumptions!$C$64*$B$2,Assumptions!$B$28)+Assumptions!$F$69*MIN(Assumptions!$C$65*$B$2,Assumptions!$B$28))*Assumptions!$B$27*B9 -> 23760 | C13: =(Assumptions!$D$69*MIN(Assumptions!$C$63*$B$2,Assumptions!$B$28)+Assumptions!$E$69*MIN(Assumptions!$C$64*$B$2,Assumptions!$B$28)+Assumptions!$F$69*MIN(Assumptions!$C$65*$B$2,Assumptions!$B$28))*Assumptions!$B$27*C9 -> 69120 | D13: =(Assumptions!$D$69*MIN(Assumptions!$C$63*$B$2,Assumptions!$B$28)+Assumptions!$E$69*MIN(Assumptions!$C$64*$B$2,Assumptions!$B$28)+Assumptions!$F$69*MIN(Assumptions!$C$65*$B$2,Assumptions!$B$28))*Assumptions!$B$27*D9 -> 86400 | E13: =(Assumptions!$D$69*MIN(Assumptions!$C$63*$B$2,Assumptions!$B$28)+Assumptions!$E$69*MIN(Assumptions!$C$64*$B$2,Assumptions!$B$28)+Assumptions!$F$69*MIN(Assumptions!$C$65*$B$2,Assumptions!$B$28))*Assumptions!$B$27*E9 -> 86400 | F13: =(Assumptions!$D$69*MIN(Assumptions!$C$63*$B$2,Assumptions!$B$28)+Assumptions!$E$69*MIN(Assumptions!$C$64*$B$2,Assumptions!$B$28)+Assumptions!$F$69*MIN(Assumptions!$C$65*$B$2,Assumptions!$B$28))*Assumptions!$B$27*F9 -> 86400 | G13: =(Assumptions!$D$69*MIN(Assumptions!$C$63*$B$2,Assumptions!$B$28)+Assumptions!$E$69*MIN(Assumptions!$C$64*$B$2,Assumptions!$B$28)+Assumptions!$F$69*MIN(Assumptions!$C$65*$B$2,Assumptions!$B$28))*Assumptions!$B$27*G9 -> 86400
A14: Bay hire | B14: =(Assumptions!$D$69*MIN(Assumptions!$C$63*$B$2,Assumptions!$B$28)*Assumptions!$D$63+Assumptions!$E$69*MIN(Assumptions!$C$64*$B$2,Assumptions!$B$28)*Assumptions!$D$64+Assumptions!$F$69*MIN(Assumptions!$C$65*$B$2,Assumptions!$B$28)*Assumptions!$D$65)*Assumptions!$B$27*B9 -> 12355200 | C14: =(Assumptions!$D$69*MIN(Assumptions!$C$63*$B$2,Assumptions!$B$28)*Assumptions!$D$63+Assumptions!$E$69*MIN(Assumptions!$C$64*$B$2,Assumptions!$B$28)*Assumptions!$D$64+Assumptions!$F$69*MIN(Assumptions!$C$65*$B$2,Assumptions!$B$28)*Assumptions!$D$65)*Assumptions!$B$27*C9 -> 35942400 | D14: =(Assumptions!$D$69*MIN(Assumptions!$C$63*$B$2,Assumptions!$B$28)*Assumptions!$D$63+Assumptions!$E$69*MIN(Assumptions!$C$64*$B$2,Assumptions!$B$28)*Assumptions!$D$64+Assumptions!$F$69*MIN(Assumptions!$C$65*$B$2,Assumptions!$B$28)*Assumptions!$D$65)*Assumptions!$B$27*D9 -> 44928000 | E14: =(Assumptions!$D$69*MIN(Assumptions!$C$63*$B$2,Assumptions!$B$28)*Assumptions!$D$63+Assumptions!$E$69*MIN(Assumptions!$C$64*$B$2,Assumptions!$B$28)*Assumptions!$D$64+Assumptions!$F$69*MIN(Assumptions!$C$65*$B$2,Assumptions!$B$28)*Assumptions!$D$65)*Assumptions!$B$27*E9 -> 44928000 | F14: =(Assumptions!$D$69*MIN(Assumptions!$C$63*$B$2,Assumptions!$B$28)*Assumptions!$D$63+Assumptions!$E$69*MIN(Assumptions!$C$64*$B$2,Assumptions!$B$28)*Assumptions!$D$64+Assumptions!$F$69*MIN(Assumptions!$C$65*$B$2,Assumptions!$B$28)*Assumptions!$D$65)*Assumptions!$B$27*F9 -> 44928000 | G14: =(Assumptions!$D$69*MIN(Assumptions!$C$63*$B$2,Assumptions!$B$28)*Assumptions!$D$63+Assumptions!$E$69*MIN(Assumptions!$C$64*$B$2,Assumptions!$B$28)*Assumptions!$D$64+Assumptions!$F$69*MIN(Assumptions!$C$65*$B$2,Assumptions!$B$28)*Assumptions!$D$65)*Assumptions!$B$27*G9 -> 44928000
A15: Golf add-on | B15: =Assumptions!$G$69*Assumptions!$B$33*Assumptions!$B$35*$B$2*IF(B7=0,Assumptions!$B$36,IF(B7=1,Assumptions!$B$37,1))*Assumptions!$B$34*12*B8 -> 986172.35 | C15: =Assumptions!$G$69*Assumptions!$B$33*Assumptions!$B$35*$B$2*IF(C7=0,Assumptions!$B$36,IF(C7=1,Assumptions!$B$37,1))*Assumptions!$B$34*12*C8 -> 3698146.3 | D15: =Assumptions!$G$69*Assumptions!$B$33*Assumptions!$B$35*$B$2*IF(D7=0,Assumptions!$B$36,IF(D7=1,Assumptions!$B$37,1))*Assumptions!$B$34*12*D8 -> 4930861.8 | E15: =Assumptions!$G$69*Assumptions!$B$33*Assumptions!$B$35*$B$2*IF(E7=0,Assumptions!$B$36,IF(E7=1,Assumptions!$B$37,1))*Assumptions!$B$34*12*E8 -> 4930861.8 | F15: =Assumptions!$G$69*Assumptions!$B$33*Assumptions!$B$35*$B$2*IF(F7=0,Assumptions!$B$36,IF(F7=1,Assumptions!$B$37,1))*Assumptions!$B$34*12*F8 -> 4930861.8 | G15: =Assumptions!$G$69*Assumptions!$B$33*Assumptions!$B$35*$B$2*IF(G7=0,Assumptions!$B$36,IF(G7=1,Assumptions!$B$37,1))*Assumptions!$B$34*12*G8 -> 4930861.8
A16: Leagues, events, corporate | B16: =B11*Assumptions!$B$40*B9 -> 440000 | C16: =C11*Assumptions!$B$40*C9 -> 1280000 | D16: =D11*Assumptions!$B$40*D9 -> 1600000 | E16: =E11*Assumptions!$B$40*E9 -> 1600000 | F16: =F11*Assumptions!$B$40*F9 -> 1600000 | G16: =G11*Assumptions!$B$40*G9 -> 1600000
A17: Insured shot, net of premium | B17: =B13*Assumptions!$B$45 -> 564300 | C17: =C13*Assumptions!$B$45 -> 1641600 | D17: =D13*Assumptions!$B$45 -> 2052000 | E17: =E13*Assumptions!$B$45 -> 2052000 | F17: =F13*Assumptions!$B$45 -> 2052000 | G17: =G13*Assumptions!$B$45 -> 2052000
A18: Naming partner | B18: =B11*Assumptions!$B$41*B8 -> 500000 | C18: =C11*Assumptions!$B$41*C8 -> 1000000 | D18: =D11*Assumptions!$B$41*D8 -> 1000000 | E18: =E11*Assumptions!$B$41*E8 -> 1000000 | F18: =F11*Assumptions!$B$41*F8 -> 1000000 | G18: =G11*Assumptions!$B$41*G8 -> 1000000
A19: Golfzon service and software | B19: =(Assumptions!$D$69*Assumptions!$B$63*Assumptions!$B$12+Assumptions!$E$69*Assumptions!$B$64*Assumptions!$B$12+Assumptions!$F$69*Assumptions!$B$65*Assumptions!$B$12)*Assumptions!$B$51*B8 -> 888000 | C19: =(Assumptions!$D$69*Assumptions!$B$63*Assumptions!$B$12+Assumptions!$E$69*Assumptions!$B$64*Assumptions!$B$12+Assumptions!$F$69*Assumptions!$B$65*Assumptions!$B$12)*Assumptions!$B$51*C8 -> 1776000 | D19: =(Assumptions!$D$69*Assumptions!$B$63*Assumptions!$B$12+Assumptions!$E$69*Assumptions!$B$64*Assumptions!$B$12+Assumptions!$F$69*Assumptions!$B$65*Assumptions!$B$12)*Assumptions!$B$51*D8 -> 1776000 | E19: =(Assumptions!$D$69*Assumptions!$B$63*Assumptions!$B$12+Assumptions!$E$69*Assumptions!$B$64*Assumptions!$B$12+Assumptions!$F$69*Assumptions!$B$65*Assumptions!$B$12)*Assumptions!$B$51*E8 -> 1776000 | F19: =(Assumptions!$D$69*Assumptions!$B$63*Assumptions!$B$12+Assumptions!$E$69*Assumptions!$B$64*Assumptions!$B$12+Assumptions!$F$69*Assumptions!$B$65*Assumptions!$B$12)*Assumptions!$B$51*F8 -> 1776000 | G19: =(Assumptions!$D$69*Assumptions!$B$63*Assumptions!$B$12+Assumptions!$E$69*Assumptions!$B$64*Assumptions!$B$12+Assumptions!$F$69*Assumptions!$B$65*Assumptions!$B$12)*Assumptions!$B$51*G8 -> 1776000
A20: Consumables and maintenance | B20: =B11*Assumptions!$B$52*B8 -> 480000 | C20: =C11*Assumptions!$B$52*C8 -> 960000 | D20: =D11*Assumptions!$B$52*D8 -> 960000 | E20: =E11*Assumptions!$B$52*E8 -> 960000 | F20: =F11*Assumptions!$B$52*F8 -> 960000 | G20: =G11*Assumptions!$B$52*G8 -> 960000
A21: Asset insurance | B21: =Debt!$D$5*Assumptions!$B$50*B8 -> 288600 | C21: =Debt!$D$5*Assumptions!$B$50*C8 -> 577200 | D21: =Debt!$D$5*Assumptions!$B$50*D8 -> 577200 | E21: =Debt!$D$5*Assumptions!$B$50*E8 -> 577200 | F21: =Debt!$D$5*Assumptions!$B$50*F8 -> 577200 | G21: =Debt!$D$5*Assumptions!$B$50*G8 -> 577200
A23: Phase 2
A24: Bay age, years | B24: =2027-Assumptions!$B$70 -> -1 | C24: =2028-Assumptions!$B$70 -> 0 | D24: =2029-Assumptions!$B$70 -> 1 | E24: =2030-Assumptions!$B$70 -> 2 | F24: =2031-Assumptions!$B$70 -> 3 | G24: =2032-Assumptions!$B$70 -> 4
A25: Share of year live | B25: =IF(B24<0,0,IF(B24=0,Assumptions!$C$70,1)) -> 0 | C25: =IF(C24<0,0,IF(C24=0,Assumptions!$C$70,1)) -> 0.5 | D25: =IF(D24<0,0,IF(D24=0,Assumptions!$C$70,1)) -> 1 | E25: =IF(E24<0,0,IF(E24=0,Assumptions!$C$70,1)) -> 1 | F25: =IF(F24<0,0,IF(F24=0,Assumptions!$C$70,1)) -> 1 | G25: =IF(G24<0,0,IF(G24=0,Assumptions!$C$70,1)) -> 1
A26: Use factor (live × ramp) | B26: =B25*IF(B24=0,Assumptions!$B$56,IF(B24=1,Assumptions!$B$57,1)) -> 0 | C26: =C25*IF(C24=0,Assumptions!$B$56,IF(C24=1,Assumptions!$B$57,1)) -> 0.275 | D26: =D25*IF(D24=0,Assumptions!$B$56,IF(D24=1,Assumptions!$B$57,1)) -> 0.8 | E26: =E25*IF(E24=0,Assumptions!$B$56,IF(E24=1,Assumptions!$B$57,1)) -> 1 | F26: =F25*IF(F24=0,Assumptions!$B$56,IF(F24=1,Assumptions!$B$57,1)) -> 1 | G26: =G25*IF(G24=0,Assumptions!$B$56,IF(G24=1,Assumptions!$B$57,1)) -> 1
A27: Capex in year | B27: =IF(B24=0,Debt!$J$5,0) -> 0 | C27: =IF(C24=0,Debt!$J$5,0) -> 84175000 | D27: =IF(D24=0,Debt!$J$5,0) -> 0 | E27: =IF(E24=0,Debt!$J$5,0) -> 0 | F27: =IF(F24=0,Debt!$J$5,0) -> 0 | G27: =IF(G24=0,Debt!$J$5,0) -> 0
A28: Bays live | B28: =IF(B24>=0,SUM(Assumptions!$D$70:$F$70),0) -> 0 | C28: =IF(C24>=0,SUM(Assumptions!$D$70:$F$70),0) -> 100 | D28: =IF(D24>=0,SUM(Assumptions!$D$70:$F$70),0) -> 100 | E28: =IF(E24>=0,SUM(Assumptions!$D$70:$F$70),0) -> 100 | F28: =IF(F24>=0,SUM(Assumptions!$D$70:$F$70),0) -> 100 | G28: =IF(G24>=0,SUM(Assumptions!$D$70:$F$70),0) -> 100
A29: Clubs live | B29: =IF(B24>=0,Assumptions!$G$70,0) -> 0 | C29: =IF(C24>=0,Assumptions!$G$70,0) -> 50 | D29: =IF(D24>=0,Assumptions!$G$70,0) -> 50 | E29: =IF(E24>=0,Assumptions!$G$70,0) -> 50 | F29: =IF(F24>=0,Assumptions!$G$70,0) -> 50 | G29: =IF(G24>=0,Assumptions!$G$70,0) -> 50
A30: Booked hours | B30: =(Assumptions!$D$70*MIN(Assumptions!$C$63*$B$2,Assumptions!$B$28)+Assumptions!$E$70*MIN(Assumptions!$C$64*$B$2,Assumptions!$B$28)+Assumptions!$F$70*MIN(Assumptions!$C$65*$B$2,Assumptions!$B$28))*Assumptions!$B$27*B26 -> 0 | C30: =(Assumptions!$D$70*MIN(Assumptions!$C$63*$B$2,Assumptions!$B$28)+Assumptions!$E$70*MIN(Assumptions!$C$64*$B$2,Assumptions!$B$28)+Assumptions!$F$70*MIN(Assumptions!$C$65*$B$2,Assumptions!$B$28))*Assumptions!$B$27*C26 -> 49005 | D30: =(Assumptions!$D$70*MIN(Assumptions!$C$63*$B$2,Assumptions!$B$28)+Assumptions!$E$70*MIN(Assumptions!$C$64*$B$2,Assumptions!$B$28)+Assumptions!$F$70*MIN(Assumptions!$C$65*$B$2,Assumptions!$B$28))*Assumptions!$B$27*D26 -> 142560 | E30: =(Assumptions!$D$70*MIN(Assumptions!$C$63*$B$2,Assumptions!$B$28)+Assumptions!$E$70*MIN(Assumptions!$C$64*$B$2,Assumptions!$B$28)+Assumptions!$F$70*MIN(Assumptions!$C$65*$B$2,Assumptions!$B$28))*Assumptions!$B$27*E26 -> 178200 | F30: =(Assumptions!$D$70*MIN(Assumptions!$C$63*$B$2,Assumptions!$B$28)+Assumptions!$E$70*MIN(Assumptions!$C$64*$B$2,Assumptions!$B$28)+Assumptions!$F$70*MIN(Assumptions!$C$65*$B$2,Assumptions!$B$28))*Assumptions!$B$27*F26 -> 178200 | G30: =(Assumptions!$D$70*MIN(Assumptions!$C$63*$B$2,Assumptions!$B$28)+Assumptions!$E$70*MIN(Assumptions!$C$64*$B$2,Assumptions!$B$28)+Assumptions!$F$70*MIN(Assumptions!$C$65*$B$2,Assumptions!$B$28))*Assumptions!$B$27*G26 -> 178200
A31: Bay hire | B31: =(Assumptions!$D$70*MIN(Assumptions!$C$63*$B$2,Assumptions!$B$28)*Assumptions!$D$63+Assumptions!$E$70*MIN(Assumptions!$C$64*$B$2,Assumptions!$B$28)*Assumptions!$D$64+Assumptions!$F$70*MIN(Assumptions!$C$65*$B$2,Assumptions!$B$28)*Assumptions!$D$65)*Assumptions!$B$27*B26 -> 0 | C31: =(Assumptions!$D$70*MIN(Assumptions!$C$63*$B$2,Assumptions!$B$28)*Assumptions!$D$63+Assumptions!$E$70*MIN(Assumptions!$C$64*$B$2,Assumptions!$B$28)*Assumptions!$D$64+Assumptions!$F$70*MIN(Assumptions!$C$65*$B$2,Assumptions!$B$28)*Assumptions!$D$65)*Assumptions!$B$27*C26 -> 17641800 | D31: =(Assumptions!$D$70*MIN(Assumptions!$C$63*$B$2,Assumptions!$B$28)*Assumptions!$D$63+Assumptions!$E$70*MIN(Assumptions!$C$64*$B$2,Assumptions!$B$28)*Assumptions!$D$64+Assumptions!$F$70*MIN(Assumptions!$C$65*$B$2,Assumptions!$B$28)*Assumptions!$D$65)*Assumptions!$B$27*D26 -> 51321600 | E31: =(Assumptions!$D$70*MIN(Assumptions!$C$63*$B$2,Assumptions!$B$28)*Assumptions!$D$63+Assumptions!$E$70*MIN(Assumptions!$C$64*$B$2,Assumptions!$B$28)*Assumptions!$D$64+Assumptions!$F$70*MIN(Assumptions!$C$65*$B$2,Assumptions!$B$28)*Assumptions!$D$65)*Assumptions!$B$27*E26 -> 64152000 | F31: =(Assumptions!$D$70*MIN(Assumptions!$C$63*$B$2,Assumptions!$B$28)*Assumptions!$D$63+Assumptions!$E$70*MIN(Assumptions!$C$64*$B$2,Assumptions!$B$28)*Assumptions!$D$64+Assumptions!$F$70*MIN(Assumptions!$C$65*$B$2,Assumptions!$B$28)*Assumptions!$D$65)*Assumptions!$B$27*F26 -> 64152000 | G31: =(Assumptions!$D$70*MIN(Assumptions!$C$63*$B$2,Assumptions!$B$28)*Assumptions!$D$63+Assumptions!$E$70*MIN(Assumptions!$C$64*$B$2,Assumptions!$B$28)*Assumptions!$D$64+Assumptions!$F$70*MIN(Assumptions!$C$65*$B$2,Assumptions!$B$28)*Assumptions!$D$65)*Assumptions!$B$27*G26 -> 64152000
A32: Golf add-on | B32: =Assumptions!$G$70*Assumptions!$B$33*Assumptions!$B$35*$B$2*IF(B24=0,Assumptions!$B$36,IF(B24=1,Assumptions!$B$37,1))*Assumptions!$B$34*12*B25 -> 0 | C32: =Assumptions!$G$70*Assumptions!$B$33*Assumptions!$B$35*$B$2*IF(C24=0,Assumptions!$B$36,IF(C24=1,Assumptions!$B$37,1))*Assumptions!$B$34*12*C25 -> 2465430.9 | D32: =Assumptions!$G$70*Assumptions!$B$33*Assumptions!$B$35*$B$2*IF(D24=0,Assumptions!$B$36,IF(D24=1,Assumptions!$B$37,1))*Assumptions!$B$34*12*D25 -> 9245365.8 | E32: =Assumptions!$G$70*Assumptions!$B$33*Assumptions!$B$35*$B$2*IF(E24=0,Assumptions!$B$36,IF(E24=1,Assumptions!$B$37,1))*Assumptions!$B$34*12*E25 -> 12327154 | F32: =Assumptions!$G$70*Assumptions!$B$33*Assumptions!$B$35*$B$2*IF(F24=0,Assumptions!$B$36,IF(F24=1,Assumptions!$B$37,1))*Assumptions!$B$34*12*F25 -> 12327154 | G32: =Assumptions!$G$70*Assumptions!$B$33*Assumptions!$B$35*$B$2*IF(G24=0,Assumptions!$B$36,IF(G24=1,Assumptions!$B$37,1))*Assumptions!$B$34*12*G25 -> 12327154
A33: Leagues, events, corporate | B33: =B28*Assumptions!$B$40*B26 -> 0 | C33: =C28*Assumptions!$B$40*C26 -> 1100000 | D33: =D28*Assumptions!$B$40*D26 -> 3200000 | E33: =E28*Assumptions!$B$40*E26 -> 4000000 | F33: =F28*Assumptions!$B$40*F26 -> 4000000 | G33: =G28*Assumptions!$B$40*G26 -> 4000000
A34: Insured shot, net of premium | B34: =B30*Assumptions!$B$45 -> 0 | C34: =C30*Assumptions!$B$45 -> 1163868.8 | D34: =D30*Assumptions!$B$45 -> 3385800 | E34: =E30*Assumptions!$B$45 -> 4232250 | F34: =F30*Assumptions!$B$45 -> 4232250 | G34: =G30*Assumptions!$B$45 -> 4232250
A35: Naming partner | B35: =B28*Assumptions!$B$41*B25 -> 0 | C35: =C28*Assumptions!$B$41*C25 -> 1250000 | D35: =D28*Assumptions!$B$41*D25 -> 2500000 | E35: =E28*Assumptions!$B$41*E25 -> 2500000 | F35: =F28*Assumptions!$B$41*F25 -> 2500000 | G35: =G28*Assumptions!$B$41*G25 -> 2500000
A36: Golfzon service and software | B36: =(Assumptions!$D$70*Assumptions!$B$63*Assumptions!$B$12+Assumptions!$E$70*Assumptions!$B$64*Assumptions!$B$12+Assumptions!$F$70*Assumptions!$B$65*Assumptions!$B$12)*Assumptions!$B$51*B25 -> 0 | C36: =(Assumptions!$D$70*Assumptions!$B$63*Assumptions!$B$12+Assumptions!$E$70*Assumptions!$B$64*Assumptions!$B$12+Assumptions!$F$70*Assumptions!$B$65*Assumptions!$B$12)*Assumptions!$B$51*C25 -> 1295000 | D36: =(Assumptions!$D$70*Assumptions!$B$63*Assumptions!$B$12+Assumptions!$E$70*Assumptions!$B$64*Assumptions!$B$12+Assumptions!$F$70*Assumptions!$B$65*Assumptions!$B$12)*Assumptions!$B$51*D25 -> 2590000 | E36: =(Assumptions!$D$70*Assumptions!$B$63*Assumptions!$B$12+Assumptions!$E$70*Assumptions!$B$64*Assumptions!$B$12+Assumptions!$F$70*Assumptions!$B$65*Assumptions!$B$12)*Assumptions!$B$51*E25 -> 2590000 | F36: =(Assumptions!$D$70*Assumptions!$B$63*Assumptions!$B$12+Assumptions!$E$70*Assumptions!$B$64*Assumptions!$B$12+Assumptions!$F$70*Assumptions!$B$65*Assumptions!$B$12)*Assumptions!$B$51*F25 -> 2590000 | G36: =(Assumptions!$D$70*Assumptions!$B$63*Assumptions!$B$12+Assumptions!$E$70*Assumptions!$B$64*Assumptions!$B$12+Assumptions!$F$70*Assumptions!$B$65*Assumptions!$B$12)*Assumptions!$B$51*G25 -> 2590000
A37: Consumables and maintenance | B37: =B28*Assumptions!$B$52*B25 -> 0 | C37: =C28*Assumptions!$B$52*C25 -> 1200000 | D37: =D28*Assumptions!$B$52*D25 -> 2400000 | E37: =E28*Assumptions!$B$52*E25 -> 2400000 | F37: =F28*Assumptions!$B$52*F25 -> 2400000 | G37: =G28*Assumptions!$B$52*G25 -> 2400000
A38: Asset insurance | B38: =Debt!$J$5*Assumptions!$B$50*B25 -> 0 | C38: =Debt!$J$5*Assumptions!$B$50*C25 -> 420875 | D38: =Debt!$J$5*Assumptions!$B$50*D25 -> 841750 | E38: =Debt!$J$5*Assumptions!$B$50*E25 -> 841750 | F38: =Debt!$J$5*Assumptions!$B$50*F25 -> 841750 | G38: =Debt!$J$5*Assumptions!$B$50*G25 -> 841750
A40: Phase 3
A41: Bay age, years | B41: =2027-Assumptions!$B$71 -> -2 | C41: =2028-Assumptions!$B$71 -> -1 | D41: =2029-Assumptions!$B$71 -> 0 | E41: =2030-Assumptions!$B$71 -> 1 | F41: =2031-Assumptions!$B$71 -> 2 | G41: =2032-Assumptions!$B$71 -> 3
A42: Share of year live | B42: =IF(B41<0,0,IF(B41=0,Assumptions!$C$71,1)) -> 0 | C42: =IF(C41<0,0,IF(C41=0,Assumptions!$C$71,1)) -> 0 | D42: =IF(D41<0,0,IF(D41=0,Assumptions!$C$71,1)) -> 0.6 | E42: =IF(E41<0,0,IF(E41=0,Assumptions!$C$71,1)) -> 1 | F42: =IF(F41<0,0,IF(F41=0,Assumptions!$C$71,1)) -> 1 | G42: =IF(G41<0,0,IF(G41=0,Assumptions!$C$71,1)) -> 1
A43: Use factor (live × ramp) | B43: =B42*IF(B41=0,Assumptions!$B$56,IF(B41=1,Assumptions!$B$57,1)) -> 0 | C43: =C42*IF(C41=0,Assumptions!$B$56,IF(C41=1,Assumptions!$B$57,1)) -> 0 | D43: =D42*IF(D41=0,Assumptions!$B$56,IF(D41=1,Assumptions!$B$57,1)) -> 0.33 | E43: =E42*IF(E41=0,Assumptions!$B$56,IF(E41=1,Assumptions!$B$57,1)) -> 0.8 | F43: =F42*IF(F41=0,Assumptions!$B$56,IF(F41=1,Assumptions!$B$57,1)) -> 1 | G43: =G42*IF(G41=0,Assumptions!$B$56,IF(G41=1,Assumptions!$B$57,1)) -> 1
A44: Capex in year | B44: =IF(B41=0,Debt!$P$5,0) -> 0 | C44: =IF(C41=0,Debt!$P$5,0) -> 0 | D44: =IF(D41=0,Debt!$P$5,0) -> 37999000 | E44: =IF(E41=0,Debt!$P$5,0) -> 0 | F44: =IF(F41=0,Debt!$P$5,0) -> 0 | G44: =IF(G41=0,Debt!$P$5,0) -> 0
...

Sheet Chain low
A1: The chain, 2027 to 2032 — low case (fixed at the low multiplier)
A2: Utilisation multiplier | B2: =Assumptions!$B$7 -> 0.7
A4: Year | B4: 2027 | C4: 2028 | D4: 2029 | E4: 2030 | F4: 2031 | G4: 2032
A6: Phase 1
A7: Bay age, years | B7: =2027-Assumptions!$B$69 -> 0 | C7: =2028-Assumptions!$B$69 -> 1 | D7: =2029-Assumptions!$B$69 -> 2 | E7: =2030-Assumptions!$B$69 -> 3 | F7: =2031-Assumptions!$B$69 -> 4 | G7: =2032-Assumptions!$B$69 -> 5
A8: Share of year live | B8: =IF(B7<0,0,IF(B7=0,Assumptions!$C$69,1)) -> 0.5 | C8: =IF(C7<0,0,IF(C7=0,Assumptions!$C$69,1)) -> 1 | D8: =IF(D7<0,0,IF(D7=0,Assumptions!$C$69,1)) -> 1 | E8: =IF(E7<0,0,IF(E7=0,Assumptions!$C$69,1)) -> 1 | F8: =IF(F7<0,0,IF(F7=0,Assumptions!$C$69,1)) -> 1 | G8: =IF(G7<0,0,IF(G7=0,Assumptions!$C$69,1)) -> 1
A9: Use factor (live × ramp) | B9: =B8*IF(B7=0,Assumptions!$B$56,IF(B7=1,Assumptions!$B$57,1)) -> 0.275 | C9: =C8*IF(C7=0,Assumptions!$B$56,IF(C7=1,Assumptions!$B$57,1)) -> 0.8 | D9: =D8*IF(D7=0,Assumptions!$B$56,IF(D7=1,Assumptions!$B$57,1)) -> 1 | E9: =E8*IF(E7=0,Assumptions!$B$56,IF(E7=1,Assumptions!$B$57,1)) -> 1 | F9: =F8*IF(F7=0,Assumptions!$B$56,IF(F7=1,Assumptions!$B$57,1)) -> 1 | G9: =G8*IF(G7=0,Assumptions!$B$56,IF(G7=1,Assumptions!$B$57,1)) -> 1
A10: Capex in year | B10: =IF(B7=0,Debt!$D$5,0) -> 57720000 | C10: =IF(C7=0,Debt!$D$5,0) -> 0 | D10: =IF(D7=0,Debt!$D$5,0) -> 0 | E10: =IF(E7=0,Debt!$D$5,0) -> 0 | F10: =IF(F7=0,Debt!$D$5,0) -> 0 | G10: =IF(G7=0,Debt!$D$5,0) -> 0
A11: Bays live | B11: =IF(B7>=0,SUM(Assumptions!$D$69:$F$69),0) -> 40 | C11: =IF(C7>=0,SUM(Assumptions!$D$69:$F$69),0) -> 40 | D11: =IF(D7>=0,SUM(Assumptions!$D$69:$F$69),0) -> 40 | E11: =IF(E7>=0,SUM(Assumptions!$D$69:$F$69),0) -> 40 | F11: =IF(F7>=0,SUM(Assumptions!$D$69:$F$69),0) -> 40 | G11: =IF(G7>=0,SUM(Assumptions!$D$69:$F$69),0) -> 40
A12: Clubs live | B12: =IF(B7>=0,Assumptions!$G$69,0) -> 20 | C12: =IF(C7>=0,Assumptions!$G$69,0) -> 20 | D12: =IF(D7>=0,Assumptions!$G$69,0) -> 20 | E12: =IF(E7>=0,Assumptions!$G$69,0) -> 20 | F12: =IF(F7>=0,Assumptions!$G$69,0) -> 20 | G12: =IF(G7>=0,Assumptions!$G$69,0) -> 20
A13: Booked hours | B13: =(Assumptions!$D$69*MIN(Assumptions!$C$63*$B$2,Assumptions!$B$28)+Assumptions!$E$69*MIN(Assumptions!$C$64*$B$2,Assumptions!$B$28)+Assumptions!$F$69*MIN(Assumptions!$C$65*$B$2,Assumptions!$B$28))*Assumptions!$B$27*B9 -> 16632 | C13: =(Assumptions!$D$69*MIN(Assumptions!$C$63*$B$2,Assumptions!$B$28)+Assumptions!$E$69*MIN(Assumptions!$C$64*$B$2,Assumptions!$B$28)+Assumptions!$F$69*MIN(Assumptions!$C$65*$B$2,Assumptions!$B$28))*Assumptions!$B$27*C9 -> 48384 | D13: =(Assumptions!$D$69*MIN(Assumptions!$C$63*$B$2,Assumptions!$B$28)+Assumptions!$E$69*MIN(Assumptions!$C$64*$B$2,Assumptions!$B$28)+Assumptions!$F$69*MIN(Assumptions!$C$65*$B$2,Assumptions!$B$28))*Assumptions!$B$27*D9 -> 60480 | E13: =(Assumptions!$D$69*MIN(Assumptions!$C$63*$B$2,Assumptions!$B$28)+Assumptions!$E$69*MIN(Assumptions!$C$64*$B$2,Assumptions!$B$28)+Assumptions!$F$69*MIN(Assumptions!$C$65*$B$2,Assumptions!$B$28))*Assumptions!$B$27*E9 -> 60480 | F13: =(Assumptions!$D$69*MIN(Assumptions!$C$63*$B$2,Assumptions!$B$28)+Assumptions!$E$69*MIN(Assumptions!$C$64*$B$2,Assumptions!$B$28)+Assumptions!$F$69*MIN(Assumptions!$C$65*$B$2,Assumptions!$B$28))*Assumptions!$B$27*F9 -> 60480 | G13: =(Assumptions!$D$69*MIN(Assumptions!$C$63*$B$2,Assumptions!$B$28)+Assumptions!$E$69*MIN(Assumptions!$C$64*$B$2,Assumptions!$B$28)+Assumptions!$F$69*MIN(Assumptions!$C$65*$B$2,Assumptions!$B$28))*Assumptions!$B$27*G9 -> 60480
A14: Bay hire | B14: =(Assumptions!$D$69*MIN(Assumptions!$C$63*$B$2,Assumptions!$B$28)*Assumptions!$D$63+Assumptions!$E$69*MIN(Assumptions!$C$64*$B$2,Assumptions!$B$28)*Assumptions!$D$64+Assumptions!$F$69*MIN(Assumptions!$C$65*$B$2,Assumptions!$B$28)*Assumptions!$D$65)*Assumptions!$B$27*B9 -> 8648640 | C14: =(Assumptions!$D$69*MIN(Assumptions!$C$63*$B$2,Assumptions!$B$28)*Assumptions!$D$63+Assumptions!$E$69*MIN(Assumptions!$C$64*$B$2,Assumptions!$B$28)*Assumptions!$D$64+Assumptions!$F$69*MIN(Assumptions!$C$65*$B$2,Assumptions!$B$28)*Assumptions!$D$65)*Assumptions!$B$27*C9 -> 25159680 | D14: =(Assumptions!$D$69*MIN(Assumptions!$C$63*$B$2,Assumptions!$B$28)*Assumptions!$D$63+Assumptions!$E$69*MIN(Assumptions!$C$64*$B$2,Assumptions!$B$28)*Assumptions!$D$64+Assumptions!$F$69*MIN(Assumptions!$C$65*$B$2,Assumptions!$B$28)*Assumptions!$D$65)*Assumptions!$B$27*D9 -> 31449600 | E14: =(Assumptions!$D$69*MIN(Assumptions!$C$63*$B$2,Assumptions!$B$28)*Assumptions!$D$63+Assumptions!$E$69*MIN(Assumptions!$C$64*$B$2,Assumptions!$B$28)*Assumptions!$D$64+Assumptions!$F$69*MIN(Assumptions!$C$65*$B$2,Assumptions!$B$28)*Assumptions!$D$65)*Assumptions!$B$27*E9 -> 31449600 | F14: =(Assumptions!$D$69*MIN(Assumptions!$C$63*$B$2,Assumptions!$B$28)*Assumptions!$D$63+Assumptions!$E$69*MIN(Assumptions!$C$64*$B$2,Assumptions!$B$28)*Assumptions!$D$64+Assumptions!$F$69*MIN(Assumptions!$C$65*$B$2,Assumptions!$B$28)*Assumptions!$D$65)*Assumptions!$B$27*F9 -> 31449600 | G14: =(Assumptions!$D$69*MIN(Assumptions!$C$63*$B$2,Assumptions!$B$28)*Assumptions!$D$63+Assumptions!$E$69*MIN(Assumptions!$C$64*$B$2,Assumptions!$B$28)*Assumptions!$D$64+Assumptions!$F$69*MIN(Assumptions!$C$65*$B$2,Assumptions!$B$28)*Assumptions!$D$65)*Assumptions!$B$27*G9 -> 31449600
A15: Golf add-on | B15: =Assumptions!$G$69*Assumptions!$B$33*Assumptions!$B$35*$B$2*IF(B7=0,Assumptions!$B$36,IF(B7=1,Assumptions!$B$37,1))*Assumptions!$B$34*12*B8 -> 690320.65 | C15: =Assumptions!$G$69*Assumptions!$B$33*Assumptions!$B$35*$B$2*IF(C7=0,Assumptions!$B$36,IF(C7=1,Assumptions!$B$37,1))*Assumptions!$B$34*12*C8 -> 2588702.4 | D15: =Assumptions!$G$69*Assumptions!$B$33*Assumptions!$B$35*$B$2*IF(D7=0,Assumptions!$B$36,IF(D7=1,Assumptions!$B$37,1))*Assumptions!$B$34*12*D8 -> 3451603.2 | E15: =Assumptions!$G$69*Assumptions!$B$33*Assumptions!$B$35*$B$2*IF(E7=0,Assumptions!$B$36,IF(E7=1,Assumptions!$B$37,1))*Assumptions!$B$34*12*E8 -> 3451603.2 | F15: =Assumptions!$G$69*Assumptions!$B$33*Assumptions!$B$35*$B$2*IF(F7=0,Assumptions!$B$36,IF(F7=1,Assumptions!$B$37,1))*Assumptions!$B$34*12*F8 -> 3451603.2 | G15: =Assumptions!$G$69*Assumptions!$B$33*Assumptions!$B$35*$B$2*IF(G7=0,Assumptions!$B$36,IF(G7=1,Assumptions!$B$37,1))*Assumptions!$B$34*12*G8 -> 3451603.2
A16: Leagues, events, corporate | B16: =B11*Assumptions!$B$40*B9 -> 440000 | C16: =C11*Assumptions!$B$40*C9 -> 1280000 | D16: =D11*Assumptions!$B$40*D9 -> 1600000 | E16: =E11*Assumptions!$B$40*E9 -> 1600000 | F16: =F11*Assumptions!$B$40*F9 -> 1600000 | G16: =G11*Assumptions!$B$40*G9 -> 1600000
A17: Insured shot, net of premium | B17: =B13*Assumptions!$B$45 -> 395010 | C17: =C13*Assumptions!$B$45 -> 1149120 | D17: =D13*Assumptions!$B$45 -> 1436400 | E17: =E13*Assumptions!$B$45 -> 1436400 | F17: =F13*Assumptions!$B$45 -> 1436400 | G17: =G13*Assumptions!$B$45 -> 1436400
A18: Naming partner | B18: =B11*Assumptions!$B$41*B8 -> 500000 | C18: =C11*Assumptions!$B$41*C8 -> 1000000 | D18: =D11*Assumptions!$B$41*D8 -> 1000000 | E18: =E11*Assumptions!$B$41*E8 -> 1000000 | F18: =F11*Assumptions!$B$41*F8 -> 1000000 | G18: =G11*Assumptions!$B$41*G8 -> 1000000
A19: Golfzon service and software | B19: =(Assumptions!$D$69*Assumptions!$B$63*Assumptions!$B$12+Assumptions!$E$69*Assumptions!$B$64*Assumptions!$B$12+Assumptions!$F$69*Assumptions!$B$65*Assumptions!$B$12)*Assumptions!$B$51*B8 -> 888000 | C19: =(Assumptions!$D$69*Assumptions!$B$63*Assumptions!$B$12+Assumptions!$E$69*Assumptions!$B$64*Assumptions!$B$12+Assumptions!$F$69*Assumptions!$B$65*Assumptions!$B$12)*Assumptions!$B$51*C8 -> 1776000 | D19: =(Assumptions!$D$69*Assumptions!$B$63*Assumptions!$B$12+Assumptions!$E$69*Assumptions!$B$64*Assumptions!$B$12+Assumptions!$F$69*Assumptions!$B$65*Assumptions!$B$12)*Assumptions!$B$51*D8 -> 1776000 | E19: =(Assumptions!$D$69*Assumptions!$B$63*Assumptions!$B$12+Assumptions!$E$69*Assumptions!$B$64*Assumptions!$B$12+Assumptions!$F$69*Assumptions!$B$65*Assumptions!$B$12)*Assumptions!$B$51*E8 -> 1776000 | F19: =(Assumptions!$D$69*Assumptions!$B$63*Assumptions!$B$12+Assumptions!$E$69*Assumptions!$B$64*Assumptions!$B$12+Assumptions!$F$69*Assumptions!$B$65*Assumptions!$B$12)*Assumptions!$B$51*F8 -> 1776000 | G19: =(Assumptions!$D$69*Assumptions!$B$63*Assumptions!$B$12+Assumptions!$E$69*Assumptions!$B$64*Assumptions!$B$12+Assumptions!$F$69*Assumptions!$B$65*Assumptions!$B$12)*Assumptions!$B$51*G8 -> 1776000
A20: Consumables and maintenance | B20: =B11*Assumptions!$B$52*B8 -> 480000 | C20: =C11*Assumptions!$B$52*C8 -> 960000 | D20: =D11*Assumptions!$B$52*D8 -> 960000 | E20: =E11*Assumptions!$B$52*E8 -> 960000 | F20: =F11*Assumptions!$B$52*F8 -> 960000 | G20: =G11*Assumptions!$B$52*G8 -> 960000
A21: Asset insurance | B21: =Debt!$D$5*Assumptions!$B$50*B8 -> 288600 | C21: =Debt!$D$5*Assumptions!$B$50*C8 -> 577200 | D21: =Debt!$D$5*Assumptions!$B$50*D8 -> 577200 | E21: =Debt!$D$5*Assumptions!$B$50*E8 -> 577200 | F21: =Debt!$D$5*Assumptions!$B$50*F8 -> 577200 | G21: =Debt!$D$5*Assumptions!$B$50*G8 -> 577200
A23: Phase 2
A24: Bay age, years | B24: =2027-Assumptions!$B$70 -> -1 | C24: =2028-Assumptions!$B$70 -> 0 | D24: =2029-Assumptions!$B$70 -> 1 | E24: =2030-Assumptions!$B$70 -> 2 | F24: =2031-Assumptions!$B$70 -> 3 | G24: =2032-Assumptions!$B$70 -> 4
A25: Share of year live | B25: =IF(B24<0,0,IF(B24=0,Assumptions!$C$70,1)) -> 0 | C25: =IF(C24<0,0,IF(C24=0,Assumptions!$C$70,1)) -> 0.5 | D25: =IF(D24<0,0,IF(D24=0,Assumptions!$C$70,1)) -> 1 | E25: =IF(E24<0,0,IF(E24=0,Assumptions!$C$70,1)) -> 1 | F25: =IF(F24<0,0,IF(F24=0,Assumptions!$C$70,1)) -> 1 | G25: =IF(G24<0,0,IF(G24=0,Assumptions!$C$70,1)) -> 1
A26: Use factor (live × ramp) | B26: =B25*IF(B24=0,Assumptions!$B$56,IF(B24=1,Assumptions!$B$57,1)) -> 0 | C26: =C25*IF(C24=0,Assumptions!$B$56,IF(C24=1,Assumptions!$B$57,1)) -> 0.275 | D26: =D25*IF(D24=0,Assumptions!$B$56,IF(D24=1,Assumptions!$B$57,1)) -> 0.8 | E26: =E25*IF(E24=0,Assumptions!$B$56,IF(E24=1,Assumptions!$B$57,1)) -> 1 | F26: =F25*IF(F24=0,Assumptions!$B$56,IF(F24=1,Assumptions!$B$57,1)) -> 1 | G26: =G25*IF(G24=0,Assumptions!$B$56,IF(G24=1,Assumptions!$B$57,1)) -> 1
A27: Capex in year | B27: =IF(B24=0,Debt!$J$5,0) -> 0 | C27: =IF(C24=0,Debt!$J$5,0) -> 84175000 | D27: =IF(D24=0,Debt!$J$5,0) -> 0 | E27: =IF(E24=0,Debt!$J$5,0) -> 0 | F27: =IF(F24=0,Debt!$J$5,0) -> 0 | G27: =IF(G24=0,Debt!$J$5,0) -> 0
A28: Bays live | B28: =IF(B24>=0,SUM(Assumptions!$D$70:$F$70),0) -> 0 | C28: =IF(C24>=0,SUM(Assumptions!$D$70:$F$70),0) -> 100 | D28: =IF(D24>=0,SUM(Assumptions!$D$70:$F$70),0) -> 100 | E28: =IF(E24>=0,SUM(Assumptions!$D$70:$F$70),0) -> 100 | F28: =IF(F24>=0,SUM(Assumptions!$D$70:$F$70),0) -> 100 | G28: =IF(G24>=0,SUM(Assumptions!$D$70:$F$70),0) -> 100
A29: Clubs live | B29: =IF(B24>=0,Assumptions!$G$70,0) -> 0 | C29: =IF(C24>=0,Assumptions!$G$70,0) -> 50 | D29: =IF(D24>=0,Assumptions!$G$70,0) -> 50 | E29: =IF(E24>=0,Assumptions!$G$70,0) -> 50 | F29: =IF(F24>=0,Assumptions!$G$70,0) -> 50 | G29: =IF(G24>=0,Assumptions!$G$70,0) -> 50
A30: Booked hours | B30: =(Assumptions!$D$70*MIN(Assumptions!$C$63*$B$2,Assumptions!$B$28)+Assumptions!$E$70*MIN(Assumptions!$C$64*$B$2,Assumptions!$B$28)+Assumptions!$F$70*MIN(Assumptions!$C$65*$B$2,Assumptions!$B$28))*Assumptions!$B$27*B26 -> 0 | C30: =(Assumptions!$D$70*MIN(Assumptions!$C$63*$B$2,Assumptions!$B$28)+Assumptions!$E$70*MIN(Assumptions!$C$64*$B$2,Assumptions!$B$28)+Assumptions!$F$70*MIN(Assumptions!$C$65*$B$2,Assumptions!$B$28))*Assumptions!$B$27*C26 -> 34303.5 | D30: =(Assumptions!$D$70*MIN(Assumptions!$C$63*$B$2,Assumptions!$B$28)+Assumptions!$E$70*MIN(Assumptions!$C$64*$B$2,Assumptions!$B$28)+Assumptions!$F$70*MIN(Assumptions!$C$65*$B$2,Assumptions!$B$28))*Assumptions!$B$27*D26 -> 99792 | E30: =(Assumptions!$D$70*MIN(Assumptions!$C$63*$B$2,Assumptions!$B$28)+Assumptions!$E$70*MIN(Assumptions!$C$64*$B$2,Assumptions!$B$28)+Assumptions!$F$70*MIN(Assumptions!$C$65*$B$2,Assumptions!$B$28))*Assumptions!$B$27*E26 -> 124740 | F30: =(Assumptions!$D$70*MIN(Assumptions!$C$63*$B$2,Assumptions!$B$28)+Assumptions!$E$70*MIN(Assumptions!$C$64*$B$2,Assumptions!$B$28)+Assumptions!$F$70*MIN(Assumptions!$C$65*$B$2,Assumptions!$B$28))*Assumptions!$B$27*F26 -> 124740 | G30: =(Assumptions!$D$70*MIN(Assumptions!$C$63*$B$2,Assumptions!$B$28)+Assumptions!$E$70*MIN(Assumptions!$C$64*$B$2,Assumptions!$B$28)+Assumptions!$F$70*MIN(Assumptions!$C$65*$B$2,Assumptions!$B$28))*Assumptions!$B$27*G26 -> 124740
A31: Bay hire | B31: =(Assumptions!$D$70*MIN(Assumptions!$C$63*$B$2,Assumptions!$B$28)*Assumptions!$D$63+Assumptions!$E$70*MIN(Assumptions!$C$64*$B$2,Assumptions!$B$28)*Assumptions!$D$64+Assumptions!$F$70*MIN(Assumptions!$C$65*$B$2,Assumptions!$B$28)*Assumptions!$D$65)*Assumptions!$B$27*B26 -> 0 | C31: =(Assumptions!$D$70*MIN(Assumptions!$C$63*$B$2,Assumptions!$B$28)*Assumptions!$D$63+Assumptions!$E$70*MIN(Assumptions!$C$64*$B$2,Assumptions!$B$28)*Assumptions!$D$64+Assumptions!$F$70*MIN(Assumptions!$C$65*$B$2,Assumptions!$B$28)*Assumptions!$D$65)*Assumptions!$B$27*C26 -> 12349260 | D31: =(Assumptions!$D$70*MIN(Assumptions!$C$63*$B$2,Assumptions!$B$28)*Assumptions!$D$63+Assumptions!$E$70*MIN(Assumptions!$C$64*$B$2,Assumptions!$B$28)*Assumptions!$D$64+Assumptions!$F$70*MIN(Assumptions!$C$65*$B$2,Assumptions!$B$28)*Assumptions!$D$65)*Assumptions!$B$27*D26 -> 35925120 | E31: =(Assumptions!$D$70*MIN(Assumptions!$C$63*$B$2,Assumptions!$B$28)*Assumptions!$D$63+Assumptions!$E$70*MIN(Assumptions!$C$64*$B$2,Assumptions!$B$28)*Assumptions!$D$64+Assumptions!$F$70*MIN(Assumptions!$C$65*$B$2,Assumptions!$B$28)*Assumptions!$D$65)*Assumptions!$B$27*E26 -> 44906400 | F31: =(Assumptions!$D$70*MIN(Assumptions!$C$63*$B$2,Assumptions!$B$28)*Assumptions!$D$63+Assumptions!$E$70*MIN(Assumptions!$C$64*$B$2,Assumptions!$B$28)*Assumptions!$D$64+Assumptions!$F$70*MIN(Assumptions!$C$65*$B$2,Assumptions!$B$28)*Assumptions!$D$65)*Assumptions!$B$27*F26 -> 44906400 | G31: =(Assumptions!$D$70*MIN(Assumptions!$C$63*$B$2,Assumptions!$B$28)*Assumptions!$D$63+Assumptions!$E$70*MIN(Assumptions!$C$64*$B$2,Assumptions!$B$28)*Assumptions!$D$64+Assumptions!$F$70*MIN(Assumptions!$C$65*$B$2,Assumptions!$B$28)*Assumptions!$D$65)*Assumptions!$B$27*G26 -> 44906400
