Workbook

Sheet Rollout
A1: Rollout plan · 200 Golfzon bays in 130 Virgin Active clubs, 2027–2029
A2: Which clubs go first, and what each phase is worth. Everything below is a formula over the Clubs sheet; edit the yellow cells there.
A4: Phases
A6: Phase | B6: What | C6: Year | D6: Bay type | E6: Bays a club | F6: Named clubs | G6: Slots still to name | H6: Clubs in model | I6: Bays | J6: Landed capex (R) | K6: Mature revenue (R/yr) | L6: Virgin Active share (R/yr) | M6: Debt drawn (R) | N6: Get Lucky Golf equity (R)
A7: 1 | B7: Collection and flagship clubs, two Signature bays each. Johannesburg first. | C7: 2027 | D7: Signature | E7: 2 | F7: =COUNTIF(Clubs!$F$5:$F$123,A7) -> 20 | G7: =H7-F7 -> 0 | H7: 20 | I7: =SUMIF(Clubs!$F$5:$F$123,A7,Clubs!$J$5:$J$123)+G7*E7 -> 40 | J7: =SUMIF(Clubs!$F$5:$F$123,A7,Clubs!$M$5:$M$123)+G7*E7*Assumptions!$D$25 -> 57720000 | K7: =SUMIF(Clubs!$F$5:$F$123,A7,Clubs!$P$5:$P$123)+G7*E7*Assumptions!$M$25 -> 55990120 | L7: =SUMIF(Clubs!$F$5:$F$123,A7,Clubs!$Q$5:$Q$123)+G7*E7*Assumptions!$N$25 -> 10998024 | M7: =J7*Assumptions!$B$18 -> 51948000 | N7: =J7-M7 -> 5772000
A8: 2 | B8: Large metro clubs, two Play bays each. | C8: 2028 | D8: Play | E8: 2 | F8: =COUNTIF(Clubs!$F$5:$F$123,A8) -> 50 | G8: =H8-F8 -> 0 | H8: 50 | I8: =SUMIF(Clubs!$F$5:$F$123,A8,Clubs!$J$5:$J$123)+G8*E8 -> 100 | J8: =SUMIF(Clubs!$F$5:$F$123,A8,Clubs!$M$5:$M$123)+G8*E8*Assumptions!$D$25 -> 84175000 | K8: =SUMIF(Clubs!$F$5:$F$123,A8,Clubs!$P$5:$P$123)+G8*E8*Assumptions!$M$25 -> 90909551 | L8: =SUMIF(Clubs!$F$5:$F$123,A8,Clubs!$Q$5:$Q$123)+G8*E8*Assumptions!$N$25 -> 17681910 | M8: =J8*Assumptions!$B$18 -> 75757500 | N8: =J8-M8 -> 8417500
A9: 3 | B9: Every other club, one bay: Play in metros, Practice coaching bays elsewhere. | C9: 2029 | D9: Play / Practice | E9: 1 | F9: =COUNTIF(Clubs!$F$5:$F$123,A9) -> 49 | G9: =H9-F9 -> 11 | H9: 60 | I9: =SUMIF(Clubs!$F$5:$F$123,A9,Clubs!$J$5:$J$123)+G9*E9 -> 60 | J9: =SUMIF(Clubs!$F$5:$F$123,A9,Clubs!$M$5:$M$123)+G9*E9*Assumptions!$D$25 -> 37999000 | K9: =SUMIF(Clubs!$F$5:$F$123,A9,Clubs!$P$5:$P$123)+G9*E9*Assumptions!$M$25 -> 44283030 | L9: =SUMIF(Clubs!$F$5:$F$123,A9,Clubs!$Q$5:$Q$123)+G9*E9*Assumptions!$N$25 -> 8556606.1 | M9: =J9*Assumptions!$B$18 -> 34199100 | N9: =J9-M9 -> 3799900
A10: Total | F10: =SUM(F7:F9) -> 119 | G10: =SUM(G7:G9) -> 11 | H10: =SUM(H7:H9) -> 130 | I10: =SUM(I7:I9) -> 200 | J10: =SUM(J7:J9) -> 179894000 | K10: =SUM(K7:K9) -> 1.911827e+08 | L10: =SUM(L7:L9) -> 37236540 | M10: =SUM(M7:M9) -> 161904600 | N10: =SUM(N7:N9) -> 17989400
A11: Slots still to name are Practice bays at clubs not yet indexed online (Virgin Active publishes 136 clubs; 119 found). Capex and revenue for those use the Practice bay.
A12: Checks: bays should read 200 and capex 179.9m, the same as the financial model (model.json).
B13: Model capex (R) | C13: 179894000 | D13: Difference | E13: =J10-C13 -> 0
A15: Clubs by region and phase
A16: Region | B16: Phase 1 | C16: Phase 2 | D16: Phase 3 | E16: Clubs | F16: Bays | G16: Landed capex (R) | H16: Virgin Active share (R/yr)
A17: Gauteng | B17: =COUNTIFS(Clubs!$C$5:$C$123,$A17,Clubs!$F$5:$F$123,1) -> 10 | C17: =COUNTIFS(Clubs!$C$5:$C$123,$A17,Clubs!$F$5:$F$123,2) -> 26 | D17: =COUNTIFS(Clubs!$C$5:$C$123,$A17,Clubs!$F$5:$F$123,3) -> 23 | E17: =SUM(B17:D17) -> 59 | F17: =SUMIF(Clubs!$C$5:$C$123,$A17,Clubs!$J$5:$J$123) -> 95 | G17: =SUMIF(Clubs!$C$5:$C$123,$A17,Clubs!$M$5:$M$123) -> 90740650 | H17: =SUMIF(Clubs!$C$5:$C$123,$A17,Clubs!$Q$5:$Q$123) -> 18555191
A18: Western Cape | B18: =COUNTIFS(Clubs!$C$5:$C$123,$A18,Clubs!$F$5:$F$123,1) -> 6 | C18: =COUNTIFS(Clubs!$C$5:$C$123,$A18,Clubs!$F$5:$F$123,2) -> 12 | D18: =COUNTIFS(Clubs!$C$5:$C$123,$A18,Clubs!$F$5:$F$123,3) -> 8 | E18: =SUM(B18:D18) -> 26 | F18: =SUMIF(Clubs!$C$5:$C$123,$A18,Clubs!$J$5:$J$123) -> 44 | G18: =SUMIF(Clubs!$C$5:$C$123,$A18,Clubs!$M$5:$M$123) -> 42063450 | H18: =SUMIF(Clubs!$C$5:$C$123,$A18,Clubs!$Q$5:$Q$123) -> 8598424
A19: KwaZulu-Natal | B19: =COUNTIFS(Clubs!$C$5:$C$123,$A19,Clubs!$F$5:$F$123,1) -> 4 | C19: =COUNTIFS(Clubs!$C$5:$C$123,$A19,Clubs!$F$5:$F$123,2) -> 8 | D19: =COUNTIFS(Clubs!$C$5:$C$123,$A19,Clubs!$F$5:$F$123,3) -> 4 | E19: =SUM(B19:D19) -> 16 | F19: =SUMIF(Clubs!$C$5:$C$123,$A19,Clubs!$J$5:$J$123) -> 28 | G19: =SUMIF(Clubs!$C$5:$C$123,$A19,Clubs!$M$5:$M$123) -> 27128400 | H19: =SUMIF(Clubs!$C$5:$C$123,$A19,Clubs!$Q$5:$Q$123) -> 5530732.8
A20: Eastern Cape | B20: =COUNTIFS(Clubs!$C$5:$C$123,$A20,Clubs!$F$5:$F$123,1) -> 0 | C20: =COUNTIFS(Clubs!$C$5:$C$123,$A20,Clubs!$F$5:$F$123,2) -> 3 | D20: =COUNTIFS(Clubs!$C$5:$C$123,$A20,Clubs!$F$5:$F$123,3) -> 2 | E20: =SUM(B20:D20) -> 5 | F20: =SUMIF(Clubs!$C$5:$C$123,$A20,Clubs!$J$5:$J$123) -> 8 | G20: =SUMIF(Clubs!$C$5:$C$123,$A20,Clubs!$M$5:$M$123) -> 6108700 | H20: =SUMIF(Clubs!$C$5:$C$123,$A20,Clubs!$Q$5:$Q$123) -> 1311925.8
A21: Free State | B21: =COUNTIFS(Clubs!$C$5:$C$123,$A21,Clubs!$F$5:$F$123,1) -> 0 | C21: =COUNTIFS(Clubs!$C$5:$C$123,$A21,Clubs!$F$5:$F$123,2) -> 1 | D21: =COUNTIFS(Clubs!$C$5:$C$123,$A21,Clubs!$F$5:$F$123,3) -> 1 | E21: =SUM(B21:D21) -> 2 | F21: =SUMIF(Clubs!$C$5:$C$123,$A21,Clubs!$J$5:$J$123) -> 3 | G21: =SUMIF(Clubs!$C$5:$C$123,$A21,Clubs!$M$5:$M$123) -> 2212600 | H21: =SUMIF(Clubs!$C$5:$C$123,$A21,Clubs!$Q$5:$Q$123) -> 479143.8
A22: Mpumalanga | B22: =COUNTIFS(Clubs!$C$5:$C$123,$A22,Clubs!$F$5:$F$123,1) -> 0 | C22: =COUNTIFS(Clubs!$C$5:$C$123,$A22,Clubs!$F$5:$F$123,2) -> 0 | D22: =COUNTIFS(Clubs!$C$5:$C$123,$A22,Clubs!$F$5:$F$123,3) -> 2 | E22: =SUM(B22:D22) -> 2 | F22: =SUMIF(Clubs!$C$5:$C$123,$A22,Clubs!$J$5:$J$123) -> 2 | G22: =SUMIF(Clubs!$C$5:$C$123,$A22,Clubs!$M$5:$M$123) -> 1058200 | H22: =SUMIF(Clubs!$C$5:$C$123,$A22,Clubs!$Q$5:$Q$123) -> 251011.2
A23: Limpopo | B23: =COUNTIFS(Clubs!$C$5:$C$123,$A23,Clubs!$F$5:$F$123,1) -> 0 | C23: =COUNTIFS(Clubs!$C$5:$C$123,$A23,Clubs!$F$5:$F$123,2) -> 0 | D23: =COUNTIFS(Clubs!$C$5:$C$123,$A23,Clubs!$F$5:$F$123,3) -> 2 | E23: =SUM(B23:D23) -> 2 | F23: =SUMIF(Clubs!$C$5:$C$123,$A23,Clubs!$J$5:$J$123) -> 2 | G23: =SUMIF(Clubs!$C$5:$C$123,$A23,Clubs!$M$5:$M$123) -> 1058200 | H23: =SUMIF(Clubs!$C$5:$C$123,$A23,Clubs!$Q$5:$Q$123) -> 251011.2
A24: North West | B24: =COUNTIFS(Clubs!$C$5:$C$123,$A24,Clubs!$F$5:$F$123,1) -> 0 | C24: =COUNTIFS(Clubs!$C$5:$C$123,$A24,Clubs!$F$5:$F$123,2) -> 0 | D24: =COUNTIFS(Clubs!$C$5:$C$123,$A24,Clubs!$F$5:$F$123,3) -> 3 | E24: =SUM(B24:D24) -> 3 | F24: =SUMIF(Clubs!$C$5:$C$123,$A24,Clubs!$J$5:$J$123) -> 3 | G24: =SUMIF(Clubs!$C$5:$C$123,$A24,Clubs!$M$5:$M$123) -> 1587300 | H24: =SUMIF(Clubs!$C$5:$C$123,$A24,Clubs!$Q$5:$Q$123) -> 376516.8
A25: Northern Cape | B25: =COUNTIFS(Clubs!$C$5:$C$123,$A25,Clubs!$F$5:$F$123,1) -> 0 | C25: =COUNTIFS(Clubs!$C$5:$C$123,$A25,Clubs!$F$5:$F$123,2) -> 0 | D25: =COUNTIFS(Clubs!$C$5:$C$123,$A25,Clubs!$F$5:$F$123,3) -> 1 | E25: =SUM(B25:D25) -> 1 | F25: =SUMIF(Clubs!$C$5:$C$123,$A25,Clubs!$J$5:$J$123) -> 1 | G25: =SUMIF(Clubs!$C$5:$C$123,$A25,Clubs!$M$5:$M$123) -> 529100 | H25: =SUMIF(Clubs!$C$5:$C$123,$A25,Clubs!$Q$5:$Q$123) -> 125505.6
A26: Botswana | B26: =COUNTIFS(Clubs!$C$5:$C$123,$A26,Clubs!$F$5:$F$123,1) -> 0 | C26: =COUNTIFS(Clubs!$C$5:$C$123,$A26,Clubs!$F$5:$F$123,2) -> 0 | D26: =COUNTIFS(Clubs!$C$5:$C$123,$A26,Clubs!$F$5:$F$123,3) -> 1 | E26: =SUM(B26:D26) -> 1 | F26: =SUMIF(Clubs!$C$5:$C$123,$A26,Clubs!$J$5:$J$123) -> 1 | G26: =SUMIF(Clubs!$C$5:$C$123,$A26,Clubs!$M$5:$M$123) -> 529100 | H26: =SUMIF(Clubs!$C$5:$C$123,$A26,Clubs!$Q$5:$Q$123) -> 125505.6
A27: Namibia | B27: =COUNTIFS(Clubs!$C$5:$C$123,$A27,Clubs!$F$5:$F$123,1) -> 0 | C27: =COUNTIFS(Clubs!$C$5:$C$123,$A27,Clubs!$F$5:$F$123,2) -> 0 | D27: =COUNTIFS(Clubs!$C$5:$C$123,$A27,Clubs!$F$5:$F$123,3) -> 2 | E27: =SUM(B27:D27) -> 2 | F27: =SUMIF(Clubs!$C$5:$C$123,$A27,Clubs!$J$5:$J$123) -> 2 | G27: =SUMIF(Clubs!$C$5:$C$123,$A27,Clubs!$M$5:$M$123) -> 1058200 | H27: =SUMIF(Clubs!$C$5:$C$123,$A27,Clubs!$Q$5:$Q$123) -> 251011.2
A28: Total | B28: =SUM(B17:B27) -> 20 | C28: =SUM(C17:C27) -> 50 | D28: =SUM(D17:D27) -> 49 | E28: =SUM(E17:E27) -> 119 | F28: =SUM(F17:F27) -> 189 | G28: =SUM(G17:G27) -> 174073900 | H28: =SUM(H17:H27) -> 35855979
A30: Phase 1 in order · the first 20 clubs
A31: Order | B31: Club | C31: Region | D31: Area | E31: Tier | F31: Install window | G31: Bays | H31: Landed capex (R) | I31: Virgin Active share (R/yr) | J31: Why this club
A32: =Clubs!I5 -> 1 | B32: =Clubs!B5 -> Alice Lane | C32: =Clubs!C5 -> Gauteng | D32: =Clubs!D5 -> Sandton | E32: =Clubs!E5 -> Collection | F32: =Clubs!H5 -> Mid 2027 · reference zone | G32: =Clubs!J5 -> 2 | H32: =Clubs!M5 -> 2886000 | I32: =Clubs!Q5 -> 549901.2 | J32: =Clubs!R5 -> Newest Sandton Collection club. The Johannesburg flagship and the reference zone the rest of the chain is built from.
A33: =Clubs!I6 -> 2 | B33: =Clubs!B6 -> Melrose Arch | C33: =Clubs!C6 -> Gauteng | D33: =Clubs!D6 -> Johannesburg | E33: =Clubs!E6 -> Collection | F33: =Clubs!H6 -> Q3 2027 | G33: =Clubs!J6 -> 2 | H33: =Clubs!M6 -> 2886000 | I33: =Clubs!Q6 -> 549901.2 | J33: =Clubs!R6 -> Original Collection club, precinct with hospitality and retail footfall. Second Johannesburg Signature zone.
A34: =Clubs!I7 -> 3 | B34: =Clubs!B7 -> Menlyn Maine | C34: =Clubs!C7 -> Gauteng | D34: =Clubs!D7 -> Pretoria | E34: =Clubs!E7 -> Collection | F34: =Clubs!H7 -> Q3 2027 | G34: =Clubs!J7 -> 2 | H34: =Clubs!M7 -> 2886000 | I34: =Clubs!Q7 -> 549901.2 | J34: =Clubs!R7 -> Pretoria's Collection club. Anchors the east-Pretoria cluster.
A35: =Clubs!I8 -> 4 | B35: =Clubs!B8 -> Sandton | C35: =Clubs!C8 -> Gauteng | D35: =Clubs!D8 -> Sandton | E35: =Clubs!E8 -> Club | F35: =Clubs!H8 -> Q3 2027 | G35: =Clubs!J8 -> 2 | H35: =Clubs!M8 -> 2886000 | I35: =Clubs!Q8 -> 549901.2 | J35: =Clubs!R8 -> Flagship club in Sandton. High-income catchment, two Signature bays.
A36: =Clubs!I9 -> 5 | B36: =Clubs!B9 -> Bryanston | C36: =Clubs!C9 -> Gauteng | D36: =Clubs!D9 -> Sandton | E36: =Clubs!E9 -> Club | F36: =Clubs!H9 -> Q3 2027 | G36: =Clubs!J9 -> 2 | H36: =Clubs!M9 -> 2886000 | I36: =Clubs!Q9 -> 549901.2 | J36: =Clubs!R9 -> Flagship club in Sandton. High-income catchment, two Signature bays.
A37: =Clubs!I10 -> 6 | B37: =Clubs!B10 -> Morningside | C37: =Clubs!C10 -> Gauteng | D37: =Clubs!D10 -> Sandton | E37: =Clubs!E10 -> Club | F37: =Clubs!H10 -> Q3 2027 | G37: =Clubs!J10 -> 2 | H37: =Clubs!M10 -> 2886000 | I37: =Clubs!Q10 -> 549901.2 | J37: =Clubs!R10 -> Flagship club in Sandton. High-income catchment, two Signature bays.
A38: =Clubs!I11 -> 7 | B38: =Clubs!B11 -> Waterfall | C38: =Clubs!C11 -> Gauteng | D38: =Clubs!D11 -> Midrand | E38: =Clubs!E11 -> Club | F38: =Clubs!H11 -> Q3 2027 | G38: =Clubs!J11 -> 2 | H38: =Clubs!M11 -> 2886000 | I38: =Clubs!Q11 -> 549901.2 | J38: =Clubs!R11 -> Flagship club in Midrand. High-income catchment, two Signature bays.
A39: =Clubs!I12 -> 8 | B39: =Clubs!B12 -> Centurion | C39: =Clubs!C12 -> Gauteng | D39: =Clubs!D12 -> Centurion | E39: =Clubs!E12 -> Club | F39: =Clubs!H12 -> Q4 2027 | G39: =Clubs!J12 -> 2 | H39: =Clubs!M12 -> 2886000 | I39: =Clubs!Q12 -> 549901.2 | J39: =Clubs!R12 -> Already runs padel courts, so members book court time. Proves the booked-like-padel model.
A40: =Clubs!I13 -> 9 | B40: =Clubs!B13 -> Rosebank | C40: =Clubs!C13 -> Gauteng | D40: =Clubs!D13 -> Johannesburg | E40: =Clubs!E13 -> Club | F40: =Clubs!H13 -> Q4 2027 | G40: =Clubs!J13 -> 2 | H40: =Clubs!M13 -> 2886000 | I40: =Clubs!Q13 -> 549901.2 | J40: =Clubs!R13 -> Flagship club in Johannesburg. High-income catchment, two Signature bays.
A41: =Clubs!I14 -> 10 | B41: =Clubs!B14 -> Dainfern | C41: =Clubs!C14 -> Gauteng | D41: =Clubs!D14 -> Fourways | E41: =Clubs!E14 -> Club | F41: =Clubs!H14 -> Q4 2027 | G41: =Clubs!J14 -> 2 | H41: =Clubs!M14 -> 2886000 | I41: =Clubs!Q14 -> 549901.2 | J41: =Clubs!R14 -> Flagship club in Fourways. High-income catchment, two Signature bays.
A42: =Clubs!I15 -> 11 | B42: =Clubs!B15 -> Silo District | C42: =Clubs!C15 -> Western Cape | D42: =Clubs!D15 -> V&A Waterfront | E42: =Clubs!E15 -> Collection | F42: =Clubs!H15 -> Q4 2027 | G42: =Clubs!J15 -> 2 | H42: =Clubs!M15 -> 2886000 | I42: =Clubs!Q15 -> 549901.2 | J42: =Clubs!R15 -> Waterfront Collection club, tourist and corporate footfall. Cape Town Signature zone.
A43: =Clubs!I16 -> 12 | B43: =Clubs!B16 -> Wembley Square | C43: =Clubs!C16 -> Western Cape | D43: =Clubs!D16 -> Gardens | E43: =Clubs!E16 -> Collection | F43: =Clubs!H16 -> Q4 2027 | G43: =Clubs!J16 -> 2 | H43: =Clubs!M16 -> 2886000 | I43: =Clubs!Q16 -> 549901.2 | J43: =Clubs!R16 -> Reopening as the first Collection Urban Club. Design the golf zone into the new build rather than retrofit.
... A51: =Clubs!I24 -> 20 | B51: =Clubs!B24 -> Ballito | C51: =Clubs!C24 -> KwaZulu-Natal | D51: =Clubs!D24 -> North Coast | E51: =Clubs!E24 -> Club | F51: =Clubs!H24 -> Q4 2027 | G51: =Clubs!J24 -> 2 | H51: =Clubs!M24 -> 2886000 | I51: =Clubs!Q24 -> 549901.2 | J51: =Clubs!R24 -> Flagship club in North Coast. High-income catchment, two Signature bays.
...

Sheet Assumptions
A1: Assumptions · Get Lucky Golf × Virgin Active (Virgin Golf concept)
A2: Blue = input you can change. Black = formula. Every figure ties to model/model.py in the simulatorstrategy repo. ZAR ex VAT.
A4: Chain inputs
A5: Input | B5: Value | C5: Note
A6: FX (ZAR per USD) | B6: 18.5 | C6: Same FX as the Get Lucky investor model
A7: Landed factor on hardware | B7: 1.3 | C7: Freight, duty, enclosure, screen, seating, install
A8: Bookable hours per bay a year | B8: 5400 | C8: 15 hours a day × 360 days
A9: Virgin Active share of shared revenue | B9: 0.2 | C9: Opening position, negotiable (15%–25% on the pitch)
A10: Golf add-on on the Virgin Active bill (R a month) | B10: 299 | C10: Ex VAT
A11: Add-on adoption at clubs with bays | B11: 0.015 | C11: Of members, at maturity
A12: Members per club (chain average) | B12: 4580.8824 | C12: 623,000 members ÷ 136 clubs. No per-club data published
A13: Clubs in the model | B13: 130 | C13: Model phases: 20 + 50 + 60
A14: Bays in the model | B14: 200 | C14: 40 + 100 + 60
A15: Leagues, events, corporate per bay a year | B15: 40000 | C15: At maturity
A16: Naming sponsor per bay a year | B16: 25000
A17: Get Lucky insured shot, net per booked hour | B17: 23.75 | C17: R50 × 0.625 taken per hour × 76% after premium
A18: Debt share of landed capex | B18: 0.9 | C18: RMB or the bank Virgin Active prefers
A21: Bay types
A22: Bay type | B22: Golfzon system | C22: Hardware (USD) | D22: Landed capex (R) | E22: Mature utilisation | F22: Yield per booked hour (R) | G22: Booked hours a year | H22: Bay hire (R/yr) | I22: Membership add-on per bay (R/yr) | J22: Leagues and events (R/yr) | K22: Insured shot (R/yr) | L22: Sponsorship (R/yr) | M22: Revenue per bay (R/yr) | N22: Virgin Active share per bay (R/yr)
A23: Signature | B23: Golfzon TwoVision NX | C23: 60000 | D23: =C23*Assumptions!$B$6*Assumptions!$B$7 -> 1443000 | E23: 0.4 | F23: 520 | G23: =Assumptions!$B$8*E23 -> 2160 | H23: =G23*F23 -> 1123200 | I23: =Assumptions!$B$13*Assumptions!$B$12*Assumptions!$B$11*Assumptions!$B$10*12/Assumptions!$B$14 -> 160253.01 | J23: =Assumptions!$B$15 -> 40000 | K23: =G23*Assumptions!$B$17 -> 51300 | L23: =Assumptions!$B$16 -> 25000 | M23: =H23+I23+J23+K23+L23 -> 1399753 | N23: =(H23+I23+J23+K23)*Assumptions!$B$9 -> 274950.6
A24: Play | B24: Golfzon Vision Standard | C24: 35000 | D24: =C24*Assumptions!$B$6*Assumptions!$B$7 -> 841750 | E24: 0.33 | F24: 360 | G24: =Assumptions!$B$8*E24 -> 1782 | H24: =G24*F24 -> 641520 | I24: =Assumptions!$B$13*Assumptions!$B$12*Assumptions!$B$11*Assumptions!$B$10*12/Assumptions!$B$14 -> 160253.01 | J24: =Assumptions!$B$15 -> 40000 | K24: =G24*Assumptions!$B$17 -> 42322.5 | L24: =Assumptions!$B$16 -> 25000 | M24: =H24+I24+J24+K24+L24 -> 909095.51 | N24: =(H24+I24+J24+K24)*Assumptions!$B$9 -> 176819.1
A25: Practice | B25: Golfzon GDR Plus | C25: 22000 | D25: =C25*Assumptions!$B$6*Assumptions!$B$7 -> 529100 | E25: 0.3 | F25: 240 | G25: =Assumptions!$B$8*E25 -> 1620 | H25: =G25*F25 -> 388800 | I25: =Assumptions!$B$13*Assumptions!$B$12*Assumptions!$B$11*Assumptions!$B$10*12/Assumptions!$B$14 -> 160253.01 | J25: =Assumptions!$B$15 -> 40000 | K25: =G25*Assumptions!$B$17 -> 38475 | L25: =Assumptions!$B$16 -> 25000 | M25: =H25+I25+J25+K25+L25 -> 652528.01 | N25: =(H25+I25+J25+K25)*Assumptions!$B$9 -> 125505.6
A27: Utilisation is mature (year 3). The model ramps 55% in year 1 and 80% in year 2. Membership add-on is the chain figure spread evenly per bay.

Sheet Clubs
A1: Clubs · 119 Virgin Active clubs found, 116 in South Africa, in install order
A2: Yellow cells are the plan: change Phase, Order, Bays or Bay type and the money recalculates. Virgin Active publishes 136 clubs across SA, Botswana and Namibia; the rest are not indexed online.
A4: # | B4: Club | C4: Region | D4: Area | E4: Tier | F4: Phase | G4: Year | H4: Install window | I4: Order in phase | J4: Bays | K4: Bay type | L4: Golfzon system | M4: Landed capex (R) | N4: Mature booked hours a year | O4: Mature bay hire (R/yr) | P4: Mature revenue (R/yr) | Q4: Virgin Active share (R/yr) | R4: Why this club | S4: Notes | T4: Club page
A5: 1 | B5: Alice Lane | C5: Gauteng | D5: Sandton | E5: Collection | F5: 1 | G5: =INDEX(Rollout!$C$7:$C$9,F5) -> 2027 | H5: Mid 2027 · reference zone | I5: 1 | J5: 2 | K5: Signature | L5: =INDEX(Assumptions!$B$23:$B$25,MATCH(K5,Assumptions!$A$23:$A$25,0)) -> Golfzon TwoVision NX | M5: =J5*INDEX(Assumptions!$D$23:$D$25,MATCH(K5,Assumptions!$A$23:$A$25,0)) -> 2886000 | N5: =J5*INDEX(Assumptions!$G$23:$G$25,MATCH(K5,Assumptions!$A$23:$A$25,0)) -> 4320 | O5: =J5*INDEX(Assumptions!$H$23:$H$25,MATCH(K5,Assumptions!$A$23:$A$25,0)) -> 2246400 | P5: =J5*INDEX(Assumptions!$M$23:$M$25,MATCH(K5,Assumptions!$A$23:$A$25,0)) -> 2799506 | Q5: =J5*INDEX(Assumptions!$N$23:$N$25,MATCH(K5,Assumptions!$A$23:$A$25,0)) -> 549901.2 | R5: Newest Sandton Collection club. The Johannesburg flagship and the reference zone the rest of the chain is built from. | T5: https://www.virginactive.co.za/gyms/alice-lane
A6: 2 | B6: Melrose Arch | C6: Gauteng | D6: Johannesburg | E6: Collection | F6: 1 | G6: =INDEX(Rollout!$C$7:$C$9,F6) -> 2027 | H6: Q3 2027 | I6: 2 | J6: 2 | K6: Signature | L6: =INDEX(Assumptions!$B$23:$B$25,MATCH(K6,Assumptions!$A$23:$A$25,0)) -> Golfzon TwoVision NX | M6: =J6*INDEX(Assumptions!$D$23:$D$25,MATCH(K6,Assumptions!$A$23:$A$25,0)) -> 2886000 | N6: =J6*INDEX(Assumptions!$G$23:$G$25,MATCH(K6,Assumptions!$A$23:$A$25,0)) -> 4320 | O6: =J6*INDEX(Assumptions!$H$23:$H$25,MATCH(K6,Assumptions!$A$23:$A$25,0)) -> 2246400 | P6: =J6*INDEX(Assumptions!$M$23:$M$25,MATCH(K6,Assumptions!$A$23:$A$25,0)) -> 2799506 | Q6: =J6*INDEX(Assumptions!$N$23:$N$25,MATCH(K6,Assumptions!$A$23:$A$25,0)) -> 549901.2 | R6: Original Collection club, precinct with hospitality and retail footfall. Second Johannesburg Signature zone. | T6: https://www.virginactive.co.za/gyms/melrose-arch
A7: 3 | B7: Menlyn Maine | C7: Gauteng | D7: Pretoria | E7: Collection | F7: 1 | G7: =INDEX(Rollout!$C$7:$C$9,F7) -> 2027 | H7: Q3 2027 | I7: 3 | J7: 2 | K7: Signature | L7: =INDEX(Assumptions!$B$23:$B$25,MATCH(K7,Assumptions!$A$23:$A$25,0)) -> Golfzon TwoVision NX | M7: =J7*INDEX(Assumptions!$D$23:$D$25,MATCH(K7,Assumptions!$A$23:$A$25,0)) -> 2886000 | N7: =J7*INDEX(Assumptions!$G$23:$G$25,MATCH(K7,Assumptions!$A$23:$A$25,0)) -> 4320 | O7: =J7*INDEX(Assumptions!$H$23:$H$25,MATCH(K7,Assumptions!$A$23:$A$25,0)) -> 2246400 | P7: =J7*INDEX(Assumptions!$M$23:$M$25,MATCH(K7,Assumptions!$A$23:$A$25,0)) -> 2799506 | Q7: =J7*INDEX(Assumptions!$N$23:$N$25,MATCH(K7,Assumptions!$A$23:$A$25,0)) -> 549901.2 | R7: Pretoria's Collection club. Anchors the east-Pretoria cluster. | T7: https://www.virginactive.co.za/gyms/menlyn-maine
A8: 4 | B8: Sandton | C8: Gauteng | D8: Sandton | E8: Club | F8: 1 | G8: =INDEX(Rollout!$C$7:$C$9,F8) -> 2027 | H8: Q3 2027 | I8: 4 | J8: 2 | K8: Signature | L8: =INDEX(Assumptions!$B$23:$B$25,MATCH(K8,Assumptions!$A$23:$A$25,0)) -> Golfzon TwoVision NX | M8: =J8*INDEX(Assumptions!$D$23:$D$25,MATCH(K8,Assumptions!$A$23:$A$25,0)) -> 2886000 | N8: =J8*INDEX(Assumptions!$G$23:$G$25,MATCH(K8,Assumptions!$A$23:$A$25,0)) -> 4320 | O8: =J8*INDEX(Assumptions!$H$23:$H$25,MATCH(K8,Assumptions!$A$23:$A$25,0)) -> 2246400 | P8: =J8*INDEX(Assumptions!$M$23:$M$25,MATCH(K8,Assumptions!$A$23:$A$25,0)) -> 2799506 | Q8: =J8*INDEX(Assumptions!$N$23:$N$25,MATCH(K8,Assumptions!$A$23:$A$25,0)) -> 549901.2 | R8: Flagship club in Sandton. High-income catchment, two Signature bays. | T8: https://www.virginactive.co.za/gyms/sandton
A9: 5 | B9: Bryanston | C9: Gauteng | D9: Sandton | E9: Club | F9: 1 | G9: =INDEX(Rollout!$C$7:$C$9,F9) -> 2027 | H9: Q3 2027 | I9: 5 | J9: 2 | K9: Signature | L9: =INDEX(Assumptions!$B$23:$B$25,MATCH(K9,Assumptions!$A$23:$A$25,0)) -> Golfzon TwoVision NX | M9: =J9*INDEX(Assumptions!$D$23:$D$25,MATCH(K9,Assumptions!$A$23:$A$25,0)) -> 2886000 | N9: =J9*INDEX(Assumptions!$G$23:$G$25,MATCH(K9,Assumptions!$A$23:$A$25,0)) -> 4320 | O9: =J9*INDEX(Assumptions!$H$23:$H$25,MATCH(K9,Assumptions!$A$23:$A$25,0)) -> 2246400 | P9: =J9*INDEX(Assumptions!$M$23:$M$25,MATCH(K9,Assumptions!$A$23:$A$25,0)) -> 2799506 | Q9: =J9*INDEX(Assumptions!$N$23:$N$25,MATCH(K9,Assumptions!$A$23:$A$25,0)) -> 549901.2 | R9: Flagship club in Sandton. High-income catchment, two Signature bays. | T9: https://www.virginactive.co.za/gyms/bryanston
A10: 6 | B10: Morningside | C10: Gauteng | D10: Sandton | E10: Club | F10: 1 | G10: =INDEX(Rollout!$C$7:$C$9,F10) -> 2027 | H10: Q3 2027 | I10: 6 | J10: 2 | K10: Signature | L10: =INDEX(Assumptions!$B$23:$B$25,MATCH(K10,Assumptions!$A$23:$A$25,0)) -> Golfzon TwoVision NX | M10: =J10*INDEX(Assumptions!$D$23:$D$25,MATCH(K10,Assumptions!$A$23:$A$25,0)) -> 2886000 | N10: =J10*INDEX(Assumptions!$G$23:$G$25,MATCH(K10,Assumptions!$A$23:$A$25,0)) -> 4320 | O10: =J10*INDEX(Assumptions!$H$23:$H$25,MATCH(K10,Assumptions!$A$23:$A$25,0)) -> 2246400 | P10: =J10*INDEX(Assumptions!$M$23:$M$25,MATCH(K10,Assumptions!$A$23:$A$25,0)) -> 2799506 | Q10: =J10*INDEX(Assumptions!$N$23:$N$25,MATCH(K10,Assumptions!$A$23:$A$25,0)) -> 549901.2 | R10: Flagship club in Sandton. High-income catchment, two Signature bays. | T10: https://www.virginactive.co.za/gyms/morningside
A11: 7 | B11: Waterfall | C11: Gauteng | D11: Midrand | E11: Club | F11: 1 | G11: =INDEX(Rollout!$C$7:$C$9,F11) -> 2027 | H11: Q3 2027 | I11: 7 | J11: 2 | K11: Signature | L11: =INDEX(Assumptions!$B$23:$B$25,MATCH(K11,Assumptions!$A$23:$A$25,0)) -> Golfzon TwoVision NX | M11: =J11*INDEX(Assumptions!$D$23:$D$25,MATCH(K11,Assumptions!$A$23:$A$25,0)) -> 2886000 | N11: =J11*INDEX(Assumptions!$G$23:$G$25,MATCH(K11,Assumptions!$A$23:$A$25,0)) -> 4320 | O11: =J11*INDEX(Assumptions!$H$23:$H$25,MATCH(K11,Assumptions!$A$23:$A$25,0)) -> 2246400 | P11: =J11*INDEX(Assumptions!$M$23:$M$25,MATCH(K11,Assumptions!$A$23:$A$25,0)) -> 2799506 | Q11: =J11*INDEX(Assumptions!$N$23:$N$25,MATCH(K11,Assumptions!$A$23:$A$25,0)) -> 549901.2 | R11: Flagship club in Midrand. High-income catchment, two Signature bays. | T11: https://www.virginactive.co.za/gyms/waterfall
A12: 8 | B12: Centurion | C12: Gauteng | D12: Centurion | E12: Club | F12: 1 | G12: =INDEX(Rollout!$C$7:$C$9,F12) -> 2027 | H12: Q4 2027 | I12: 8 | J12: 2 | K12: Signature | L12: =INDEX(Assumptions!$B$23:$B$25,MATCH(K12,Assumptions!$A$23:$A$25,0)) -> Golfzon TwoVision NX | M12: =J12*INDEX(Assumptions!$D$23:$D$25,MATCH(K12,Assumptions!$A$23:$A$25,0)) -> 2886000 | N12: =J12*INDEX(Assumptions!$G$23:$G$25,MATCH(K12,Assumptions!$A$23:$A$25,0)) -> 4320 | O12: =J12*INDEX(Assumptions!$H$23:$H$25,MATCH(K12,Assumptions!$A$23:$A$25,0)) -> 2246400 | P12: =J12*INDEX(Assumptions!$M$23:$M$25,MATCH(K12,Assumptions!$A$23:$A$25,0)) -> 2799506 | Q12: =J12*INDEX(Assumptions!$N$23:$N$25,MATCH(K12,Assumptions!$A$23:$A$25,0)) -> 549901.2 | R12: Already runs padel courts, so members book court time. Proves the booked-like-padel model. | S12: Has padel courts | T12: https://www.virginactive.co.za/gyms/centurion
A13: 9 | B13: Rosebank | C13: Gauteng | D13: Johannesburg | E13: Club | F13: 1 | G13: =INDEX(Rollout!$C$7:$C$9,F13) -> 2027 | H13: Q4 2027 | I13: 9 | J13: 2 | K13: Signature | L13: =INDEX(Assumptions!$B$23:$B$25,MATCH(K13,Assumptions!$A$23:$A$25,0)) -> Golfzon TwoVision NX | M13: =J13*INDEX(Assumptions!$D$23:$D$25,MATCH(K13,Assumptions!$A$23:$A$25,0)) -> 2886000 | N13: =J13*INDEX(Assumptions!$G$23:$G$25,MATCH(K13,Assumptions!$A$23:$A$25,0)) -> 4320 | O13: =J13*INDEX(Assumptions!$H$23:$H$25,MATCH(K13,Assumptions!$A$23:$A$25,0)) -> 2246400 | P13: =J13*INDEX(Assumptions!$M$23:$M$25,MATCH(K13,Assumptions!$A$23:$A$25,0)) -> 2799506 | Q13: =J13*INDEX(Assumptions!$N$23:$N$25,MATCH(K13,Assumptions!$A$23:$A$25,0)) -> 549901.2 | R13: Flagship club in Johannesburg. High-income catchment, two Signature bays. | T13: https://www.virginactive.co.za/gyms/rosebank
A14: 10 | B14: Dainfern | C14: Gauteng | D14: Fourways | E14: Club | F14: 1 | G14: =INDEX(Rollout!$C$7:$C$9,F14) -> 2027 | H14: Q4 2027 | I14: 10 | J14: 2 | K14: Signature | L14: =INDEX(Assumptions!$B$23:$B$25,MATCH(K14,Assumptions!$A$23:$A$25,0)) -> Golfzon TwoVision NX | M14: =J14*INDEX(Assumptions!$D$23:$D$25,MATCH(K14,Assumptions!$A$23:$A$25,0)) -> 2886000 | N14: =J14*INDEX(Assumptions!$G$23:$G$25,MATCH(K14,Assumptions!$A$23:$A$25,0)) -> 4320 | O14: =J14*INDEX(Assumptions!$H$23:$H$25,MATCH(K14,Assumptions!$A$23:$A$25,0)) -> 2246400 | P14: =J14*INDEX(Assumptions!$M$23:$M$25,MATCH(K14,Assumptions!$A$23:$A$25,0)) -> 2799506 | Q14: =J14*INDEX(Assumptions!$N$23:$N$25,MATCH(K14,Assumptions!$A$23:$A$25,0)) -> 549901.2 | R14: Flagship club in Fourways. High-income catchment, two Signature bays. | T14: https://www.virginactive.co.za/gyms/dainfern
A15: 11 | B15: Silo District | C15: Western Cape | D15: V&A Waterfront | E15: Collection | F15: 1 | G15: =INDEX(Rollout!$C$7:$C$9,F15) -> 2027 | H15: Q4 2027 | I15: 11 | J15: 2 | K15: Signature | L15: =INDEX(Assumptions!$B$23:$B$25,MATCH(K15,Assumptions!$A$23:$A$25,0)) -> Golfzon TwoVision NX | M15: =J15*INDEX(Assumptions!$D$23:$D$25,MATCH(K15,Assumptions!$A$23:$A$25,0)) -> 2886000 | N15: =J15*INDEX(Assumptions!$G$23:$G$25,MATCH(K15,Assumptions!$A$23:$A$25,0)) -> 4320 | O15: =J15*INDEX(Assumptions!$H$23:$H$25,MATCH(K15,Assumptions!$A$23:$A$25,0)) -> 2246400 | P15: =J15*INDEX(Assumptions!$M$23:$M$25,MATCH(K15,Assumptions!$A$23:$A$25,0)) -> 2799506 | Q15: =J15*INDEX(Assumptions!$N$23:$N$25,MATCH(K15,Assumptions!$A$23:$A$25,0)) -> 549901.2 | R15: Waterfront Collection club, tourist and corporate footfall. Cape Town Signature zone. | T15: https://www.virginactive.co.za/gyms/silo-district
A16: 12 | B16: Wembley Square | C16: Western Cape | D16: Gardens | E16: Collection | F16: 1 | G16: =INDEX(Rollout!$C$7:$C$9,F16) -> 2027 | H16: Q4 2027 | I16: 12 | J16: 2 | K16: Signature | L16: =INDEX(Assumptions!$B$23:$B$25,MATCH(K16,Assumptions!$A$23:$A$25,0)) -> Golfzon TwoVision NX | M16: =J16*INDEX(Assumptions!$D$23:$D$25,MATCH(K16,Assumptions!$A$23:$A$25,0)) -> 2886000 | N16: =J16*INDEX(Assumptions!$G$23:$G$25,MATCH(K16,Assumptions!$A$23:$A$25,0)) -> 4320 | O16: =J16*INDEX(Assumptions!$H$23:$H$25,MATCH(K16,Assumptions!$A$23:$A$25,0)) -> 2246400 | P16: =J16*INDEX(Assumptions!$M$23:$M$25,MATCH(K16,Assumptions!$A$23:$A$25,0)) -> 2799506 | Q16: =J16*INDEX(Assumptions!$N$23:$N$25,MATCH(K16,Assumptions!$A$23:$A$25,0)) -> 549901.2 | R16: Reopening as the first Collection Urban Club. Design the golf zone into the new build rather than retrofit. | S16: Reopening as first Collection Urban Club | T16: https://www.virginactive.co.za/gyms/wembley-square
A17: 13 | B17: Claremont | C17: Western Cape | D17: Southern Suburbs | E17: Club | F17: 1 | G17: =INDEX(Rollout!$C$7:$C$9,F17) -> 2027 | H17: Q4 2027 | I17: 13 | J17: 2 | K17: Signature | L17: =INDEX(Assumptions!$B$23:$B$25,MATCH(K17,Assumptions!$A$23:$A$25,0)) -> Golfzon TwoVision NX | M17: =J17*INDEX(Assumptions!$D$23:$D$25,MATCH(K17,Assumptions!$A$23:$A$25,0)) -> 2886000 | N17: =J17*INDEX(Assumptions!$G$23:$G$25,MATCH(K17,Assumptions!$A$23:$A$25,0)) -> 4320 | O17: =J17*INDEX(Assumptions!$H$23:$H$25,MATCH(K17,Assumptions!$A$23:$A$25,0)) -> 2246400 | P17: =J17*INDEX(Assumptions!$M$23:$M$25,MATCH(K17,Assumptions!$A$23:$A$25,0)) -> 2799506 | Q17: =J17*INDEX(Assumptions!$N$23:$N$25,MATCH(K17,Assumptions!$A$23:$A$25,0)) -> 549901.2 | R17: Flagship club in Southern Suburbs. High-income catchment, two Signature bays. | T17: https://www.virginactive.co.za/gyms/claremont
A18: 14 | B18: Constantia | C18: Western Cape | D18: Southern Suburbs | E18: Club | F18: 1 | G18: =INDEX(Rollout!$C$7:$C$9,F18) -> 2027 | H18: Q4 2027 | I18: 14 | J18: 2 | K18: Signature | L18: =INDEX(Assumptions!$B$23:$B$25,MATCH(K18,Assumptions!$A$23:$A$25,0)) -> Golfzon TwoVision NX | M18: =J18*INDEX(Assumptions!$D$23:$D$25,MATCH(K18,Assumptions!$A$23:$A$25,0)) -> 2886000 | N18: =J18*INDEX(Assumptions!$G$23:$G$25,MATCH(K18,Assumptions!$A$23:$A$25,0)) -> 4320 | O18: =J18*INDEX(Assumptions!$H$23:$H$25,MATCH(K18,Assumptions!$A$23:$A$25,0)) -> 2246400 | P18: =J18*INDEX(Assumptions!$M$23:$M$25,MATCH(K18,Assumptions!$A$23:$A$25,0)) -> 2799506 | Q18: =J18*INDEX(Assumptions!$N$23:$N$25,MATCH(K18,Assumptions!$A$23:$A$25,0)) -> 549901.2 | R18: Flagship club in Southern Suburbs. High-income catchment, two Signature bays. | T18: https://www.virginactive.co.za/gyms/constantia
A19: 15 | B19: Century City | C19: Western Cape | D19: Century City | E19: Club | F19: 1 | G19: =INDEX(Rollout!$C$7:$C$9,F19) -> 2027 | H19: Q4 2027 | I19: 15 | J19: 2 | K19: Signature | L19: =INDEX(Assumptions!$B$23:$B$25,MATCH(K19,Assumptions!$A$23:$A$25,0)) -> Golfzon TwoVision NX | M19: =J19*INDEX(Assumptions!$D$23:$D$25,MATCH(K19,Assumptions!$A$23:$A$25,0)) -> 2886000 | N19: =J19*INDEX(Assumptions!$G$23:$G$25,MATCH(K19,Assumptions!$A$23:$A$25,0)) -> 4320 | O19: =J19*INDEX(Assumptions!$H$23:$H$25,MATCH(K19,Assumptions!$A$23:$A$25,0)) -> 2246400 | P19: =J19*INDEX(Assumptions!$M$23:$M$25,MATCH(K19,Assumptions!$A$23:$A$25,0)) -> 2799506 | Q19: =J19*INDEX(Assumptions!$N$23:$N$25,MATCH(K19,Assumptions!$A$23:$A$25,0)) -> 549901.2 | R19: Flagship club in Century City. High-income catchment, two Signature bays. | T19: https://www.virginactive.co.za/gyms/century-city
A20: 16 | B20: Tygervalley | C20: Western Cape | D20: Northern Suburbs | E20: Club | F20: 1 | G20: =INDEX(Rollout!$C$7:$C$9,F20) -> 2027 | H20: Q4 2027 | I20: 16 | J20: 2 | K20: Signature | L20: =INDEX(Assumptions!$B$23:$B$25,MATCH(K20,Assumptions!$A$23:$A$25,0)) -> Golfzon TwoVision NX | M20: =J20*INDEX(Assumptions!$D$23:$D$25,MATCH(K20,Assumptions!$A$23:$A$25,0)) -> 2886000 | N20: =J20*INDEX(Assumptions!$G$23:$G$25,MATCH(K20,Assumptions!$A$23:$A$25,0)) -> 4320 | O20: =J20*INDEX(Assumptions!$H$23:$H$25,MATCH(K20,Assumptions!$A$23:$A$25,0)) -> 2246400 | P20: =J20*INDEX(Assumptions!$M$23:$M$25,MATCH(K20,Assumptions!$A$23:$A$25,0)) -> 2799506 | Q20: =J20*INDEX(Assumptions!$N$23:$N$25,MATCH(K20,Assumptions!$A$23:$A$25,0)) -> 549901.2 | R20: Flagship club in Northern Suburbs. High-income catchment, two Signature bays. | T20: https://www.virginactive.co.za/gyms/tygervalley
A21: 17 | B21: Moses Mabhida | C21: KwaZulu-Natal | D21: Durban | E21: Collection | F21: 1 | G21: =INDEX(Rollout!$C$7:$C$9,F21) -> 2027 | H21: Q4 2027 | I21: 17 | J21: 2 | K21: Signature | L21: =INDEX(Assumptions!$B$23:$B$25,MATCH(K21,Assumptions!$A$23:$A$25,0)) -> Golfzon TwoVision NX | M21: =J21*INDEX(Assumptions!$D$23:$D$25,MATCH(K21,Assumptions!$A$23:$A$25,0)) -> 2886000 | N21: =J21*INDEX(Assumptions!$G$23:$G$25,MATCH(K21,Assumptions!$A$23:$A$25,0)) -> 4320 | O21: =J21*INDEX(Assumptions!$H$23:$H$25,MATCH(K21,Assumptions!$A$23:$A$25,0)) -> 2246400 | P21: =J21*INDEX(Assumptions!$M$23:$M$25,MATCH(K21,Assumptions!$A$23:$A$25,0)) -> 2799506 | Q21: =J21*INDEX(Assumptions!$N$23:$N$25,MATCH(K21,Assumptions!$A$23:$A$25,0)) -> 549901.2 | R21: Durban's Collection club inside the stadium. KwaZulu-Natal Signature zone. | T21: https://www.virginactive.co.za/gyms/moses-mabhida
A22: 18 | B22: Gateway | C22: KwaZulu-Natal | D22: uMhlanga | E22: Club | F22: 1 | G22: =INDEX(Rollout!$C$7:$C$9,F22) -> 2027 | H22: Q4 2027 | I22: 18 | J22: 2 | K22: Signature | L22: =INDEX(Assumptions!$B$23:$B$25,MATCH(K22,Assumptions!$A$23:$A$25,0)) -> Golfzon TwoVision NX | M22: =J22*INDEX(Assumptions!$D$23:$D$25,MATCH(K22,Assumptions!$A$23:$A$25,0)) -> 2886000 | N22: =J22*INDEX(Assumptions!$G$23:$G$25,MATCH(K22,Assumptions!$A$23:$A$25,0)) -> 4320 | O22: =J22*INDEX(Assumptions!$H$23:$H$25,MATCH(K22,Assumptions!$A$23:$A$25,0)) -> 2246400 | P22: =J22*INDEX(Assumptions!$M$23:$M$25,MATCH(K22,Assumptions!$A$23:$A$25,0)) -> 2799506 | Q22: =J22*INDEX(Assumptions!$N$23:$N$25,MATCH(K22,Assumptions!$A$23:$A$25,0)) -> 549901.2 | R22: Flagship club in uMhlanga. High-income catchment, two Signature bays. | T22: https://www.virginactive.co.za/gyms/gateway
A23: 19 | B23: La Lucia | C23: KwaZulu-Natal | D23: uMhlanga | E23: Club | F23: 1 | G23: =INDEX(Rollout!$C$7:$C$9,F23) -> 2027 | H23: Q4 2027 | I23: 19 | J23: 2 | K23: Signature | L23: =INDEX(Assumptions!$B$23:$B$25,MATCH(K23,Assumptions!$A$23:$A$25,0)) -> Golfzon TwoVision NX | M23: =J23*INDEX(Assumptions!$D$23:$D$25,MATCH(K23,Assumptions!$A$23:$A$25,0)) -> 2886000 | N23: =J23*INDEX(Assumptions!$G$23:$G$25,MATCH(K23,Assumptions!$A$23:$A$25,0)) -> 4320 | O23: =J23*INDEX(Assumptions!$H$23:$H$25,MATCH(K23,Assumptions!$A$23:$A$25,0)) -> 2246400 | P23: =J23*INDEX(Assumptions!$M$23:$M$25,MATCH(K23,Assumptions!$A$23:$A$25,0)) -> 2799506 | Q23: =J23*INDEX(Assumptions!$N$23:$N$25,MATCH(K23,Assumptions!$A$23:$A$25,0)) -> 549901.2 | R23: Flagship club in uMhlanga. High-income catchment, two Signature bays. | T23: https://www.virginactive.co.za/gyms/la-lucia
A24: 20 | B24: Ballito | C24: KwaZulu-Natal | D24: North Coast | E24: Club | F24: 1 | G24: =INDEX(Rollout!$C$7:$C$9,F24) -> 2027 | H24: Q4 2027 | I24: 20 | J24: 2 | K24: Signature | L24: =INDEX(Assumptions!$B$23:$B$25,MATCH(K24,Assumptions!$A$23:$A$25,0)) -> Golfzon TwoVision NX | M24: =J24*INDEX(Assumptions!$D$23:$D$25,MATCH(K24,Assumptions!$A$23:$A$25,0)) -> 2886000 | N24: =J24*INDEX(Assumptions!$G$23:$G$25,MATCH(K24,Assumptions!$A$23:$A$25,0)) -> 4320 | O24: =J24*INDEX(Assumptions!$H$23:$H$25,MATCH(K24,Assumptions!$A$23:$A$25,0)) -> 2246400 | P24: =J24*INDEX(Assumptions!$M$23:$M$25,MATCH(K24,Assumptions!$A$23:$A$25,0)) -> 2799506 | Q24: =J24*INDEX(Assumptions!$N$23:$N$25,MATCH(K24,Assumptions!$A$23:$A$25,0)) -> 549901.2 | R24: Flagship club in North Coast. High-income catchment, two Signature bays. | T24: https://www.virginactive.co.za/gyms/ballito
A25: 21 | B25: Sandton CBD | C25: Gauteng | D25: Sandton | E25: Club | F25: 2 | G25: =INDEX(Rollout!$C$7:$C$9,F25) -> 2028 | H25: H1 2028 | I25: 1 | J25: 2 | K25: Play | L25: =INDEX(Assumptions!$B$23:$B$25,MATCH(K25,Assumptions!$A$23:$A$25,0)) -> Golfzon Vision Standard | M25: =J25*INDEX(Assumptions!$D$23:$D$25,MATCH(K25,Assumptions!$A$23:$A$25,0)) -> 1683500 | N25: =J25*INDEX(Assumptions!$G$23:$G$25,MATCH(K25,Assumptions!$A$23:$A$25,0)) -> 3564 | O25: =J25*INDEX(Assumptions!$H$23:$H$25,MATCH(K25,Assumptions!$A$23:$A$25,0)) -> 1283040 | P25: =J25*INDEX(Assumptions!$M$23:$M$25,MATCH(K25,Assumptions!$A$23:$A$25,0)) -> 1818191 | Q25: =J25*INDEX(Assumptions!$N$23:$N$25,MATCH(K25,Assumptions!$A$23:$A$25,0)) -> 353638.2 | R25: Large metro club in Sandton. Two Play bays. | T25: https://www.virginactive.co.za/gyms/sandton-cbd
A26: 22 | B26: Sunninghill | C26: Gauteng | D26: Sandton | E26: Club | F26: 2 | G26: =INDEX(Rollout!$C$7:$C$9,F26) -> 2028 | H26: H1 2028 | I26: 2 | J26: 2 | K26: Play | L26: =INDEX(Assumptions!$B$23:$B$25,MATCH(K26,Assumptions!$A$23:$A$25,0)) -> Golfzon Vision Standard | M26: =J26*INDEX(Assumptions!$D$23:$D$25,MATCH(K26,Assumptions!$A$23:$A$25,0)) -> 1683500 | N26: =J26*INDEX(Assumptions!$G$23:$G$25,MATCH(K26,Assumptions!$A$23:$A$25,0)) -> 3564 | O26: =J26*INDEX(Assumptions!$H$23:$H$25,MATCH(K26,Assumptions!$A$23:$A$25,0)) -> 1283040 | P26: =J26*INDEX(Assumptions!$M$23:$M$25,MATCH(K26,Assumptions!$A$23:$A$25,0)) -> 1818191 | Q26: =J26*INDEX(Assumptions!$N$23:$N$25,MATCH(K26,Assumptions!$A$23:$A$25,0)) -> 353638.2 | R26: Large metro club in Sandton. Two Play bays. | T26: https://www.virginactive.co.za/gyms/sunninghill
A27: 23 | B27: Old Eds | C27: Gauteng | D27: Houghton | E27: Club | F27: 2 | G27: =INDEX(Rollout!$C$7:$C$9,F27) -> 2028 | H27: H1 2028 | I27: 3 | J27: 2 | K27: Play | L27: =INDEX(Assumptions!$B$23:$B$25,MATCH(K27,Assumptions!$A$23:$A$25,0)) -> Golfzon Vision Standard | M27: =J27*INDEX(Assumptions!$D$23:$D$25,MATCH(K27,Assumptions!$A$23:$A$25,0)) -> 1683500 | N27: =J27*INDEX(Assumptions!$G$23:$G$25,MATCH(K27,Assumptions!$A$23:$A$25,0)) -> 3564 | O27: =J27*INDEX(Assumptions!$H$23:$H$25,MATCH(K27,Assumptions!$A$23:$A$25,0)) -> 1283040 | P27: =J27*INDEX(Assumptions!$M$23:$M$25,MATCH(K27,Assumptions!$A$23:$A$25,0)) -> 1818191 | Q27: =J27*INDEX(Assumptions!$N$23:$N$25,MATCH(K27,Assumptions!$A$23:$A$25,0)) -> 353638.2 | R27: Large metro club in Houghton. Two Play bays. | T27: https://www.virginactive.co.za/gyms/old-eds
A28: 24 | B28: Victory Park | C28: Gauteng | D28: Randburg | E28: Club | F28: 2 | G28: =INDEX(Rollout!$C$7:$C$9,F28) -> 2028 | H28: H1 2028 | I28: 4 | J28: 2 | K28: Play | L28: =INDEX(Assumptions!$B$23:$B$25,MATCH(K28,Assumptions!$A$23:$A$25,0)) -> Golfzon Vision Standard | M28: =J28*INDEX(Assumptions!$D$23:$D$25,MATCH(K28,Assumptions!$A$23:$A$25,0)) -> 1683500 | N28: =J28*INDEX(Assumptions!$G$23:$G$25,MATCH(K28,Assumptions!$A$23:$A$25,0)) -> 3564 | O28: =J28*INDEX(Assumptions!$H$23:$H$25,MATCH(K28,Assumptions!$A$23:$A$25,0)) -> 1283040 | P28: =J28*INDEX(Assumptions!$M$23:$M$25,MATCH(K28,Assumptions!$A$23:$A$25,0)) -> 1818191 | Q28: =J28*INDEX(Assumptions!$N$23:$N$25,MATCH(K28,Assumptions!$A$23:$A$25,0)) -> 353638.2 | R28: Large metro club in Randburg. Two Play bays. | T28: https://www.virginactive.co.za/gyms/victory-park
... A74: 70 | B74: Fichardt Park | C74: Free State | D74: Bloemfontein | E74: Club | F74: 2 | G74: =INDEX(Rollout!$C$7:$C$9,F74) -> 2028 | H74: H2 2028 | I74: 50 | J74: 2 | K74: Play | L74: =INDEX(Assumptions!$B$23:$B$25,MATCH(K74,Assumptions!$A$23:$A$25,0)) -> Golfzon Vision Standard | M74: =J74*INDEX(Assumptions!$D$23:$D$25,MATCH(K74,Assumptions!$A$23:$A$25,0)) -> 1683500 | N74: =J74*INDEX(Assumptions!$G$23:$G$25,MATCH(K74,Assumptions!$A$23:$A$25,0)) -> 3564 | O74: =J74*INDEX(Assumptions!$H$23:$H$25,MATCH(K74,Assumptions!$A$23:$A$25,0)) -> 1283040 | P74: =J74*INDEX(Assumptions!$M$23:$M$25,MATCH(K74,Assumptions!$A$23:$A$25,0)) -> 1818191 | Q74: =J74*INDEX(Assumptions!$N$23:$N$25,MATCH(K74,Assumptions!$A$23:$A$25,0)) -> 353638.2 | R74: Large metro club in Bloemfontein. Two Play bays. | T74: https://www.virginactive.co.za/gyms/fichardt-park
A75: 71 | B75: Point | C75: Western Cape | D75: Green Point | E75: Collection | F75: 3 | G75: =INDEX(Rollout!$C$7:$C$9,F75) -> 2029 | H75: H1 2029 | I75: 1 | J75: 1 | K75: Play | L75: =INDEX(Assumptions!$B$23:$B$25,MATCH(K75,Assumptions!$A$23:$A$25,0)) -> Golfzon Vision Standard | M75: =J75*INDEX(Assumptions!$D$23:$D$25,MATCH(K75,Assumptions!$A$23:$A$25,0)) -> 841750 | N75: =J75*INDEX(Assumptions!$G$23:$G$25,MATCH(K75,Assumptions!$A$23:$A$25,0)) -> 1782 | O75: =J75*INDEX(Assumptions!$H$23:$H$25,MATCH(K75,Assumptions!$A$23:$A$25,0)) -> 641520 | P75: =J75*INDEX(Assumptions!$M$23:$M$25,MATCH(K75,Assumptions!$A$23:$A$25,0)) -> 909095.51 | Q75: =J75*INDEX(Assumptions!$N$23:$N$25,MATCH(K75,Assumptions!$A$23:$A$25,0)) -> 176819.1 | R75: Existing TrackMan simulator. Left out of Phase 1; revisit in Phase 3 when the current unit is reviewed. | S75: Has a TrackMan simulator | T75: https://www.virginactive.co.za/gyms/point
A76: 72 | B76: Milpark | C76: Gauteng | D76: Johannesburg | E76: Club | F76: 3 | G76: =INDEX(Rollout!$C$7:$C$9,F76) -> 2029 | H76: H1 2029 | I76: 2 | J76: 1 | K76: Play | L76: =INDEX(Assumptions!$B$23:$B$25,MATCH(K76,Assumptions!$A$23:$A$25,0)) -> Golfzon Vision Standard | M76: =J76*INDEX(Assumptions!$D$23:$D$25,MATCH(K76,Assumptions!$A$23:$A$25,0)) -> 841750 | N76: =J76*INDEX(Assumptions!$G$23:$G$25,MATCH(K76,Assumptions!$A$23:$A$25,0)) -> 1782 | O76: =J76*INDEX(Assumptions!$H$23:$H$25,MATCH(K76,Assumptions!$A$23:$A$25,0)) -> 641520 | P76: =J76*INDEX(Assumptions!$M$23:$M$25,MATCH(K76,Assumptions!$A$23:$A$25,0)) -> 909095.51 | Q76: =J76*INDEX(Assumptions!$N$23:$N$25,MATCH(K76,Assumptions!$A$23:$A$25,0)) -> 176819.1 | R76: Metro club in Johannesburg. One Play bay. | T76: https://www.virginactive.co.za/gyms/milpark
A77: 73 | B77: Braamfontein | C77: Gauteng | D77: Johannesburg | E77: Club | F77: 3 | G77: =INDEX(Rollout!$C$7:$C$9,F77) -> 2029 | H77: H1 2029 | I77: 3 | J77: 1 | K77: Play | L77: =INDEX(Assumptions!$B$23:$B$25,MATCH(K77,Assumptions!$A$23:$A$25,0)) -> Golfzon Vision Standard | M77: =J77*INDEX(Assumptions!$D$23:$D$25,MATCH(K77,Assumptions!$A$23:$A$25,0)) -> 841750 | N77: =J77*INDEX(Assumptions!$G$23:$G$25,MATCH(K77,Assumptions!$A$23:$A$25,0)) -> 1782 | O77: =J77*INDEX(Assumptions!$H$23:$H$25,MATCH(K77,Assumptions!$A$23:$A$25,0)) -> 641520 | P77: =J77*INDEX(Assumptions!$M$23:$M$25,MATCH(K77,Assumptions!$A$23:$A$25,0)) -> 909095.51 | Q77: =J77*INDEX(Assumptions!$N$23:$N$25,MATCH(K77,Assumptions!$A$23:$A$25,0)) -> 176819.1 | R77: Metro club in Johannesburg. One Play bay. | T77: https://www.virginactive.co.za/gyms/braamfontein
A78: 74 | B78: Roodepoort | C78: Gauteng | D78: Roodepoort | E78: Club | F78: 3 | G78: =INDEX(Rollout!$C$7:$C$9,F78) -> 2029 | H78: H1 2029 | I78: 4 | J78: 1 | K78: Play | L78: =INDEX(Assumptions!$B$23:$B$25,MATCH(K78,Assumptions!$A$23:$A$25,0)) -> Golfzon Vision Standard | M78: =J78*INDEX(Assumptions!$D$23:$D$25,MATCH(K78,Assumptions!$A$23:$A$25,0)) -> 841750 | N78: =J78*INDEX(Assumptions!$G$23:$G$25,MATCH(K78,Assumptions!$A$23:$A$25,0)) -> 1782 | O78: =J78*INDEX(Assumptions!$H$23:$H$25,MATCH(K78,Assumptions!$A$23:$A$25,0)) -> 641520 | P78: =J78*INDEX(Assumptions!$M$23:$M$25,MATCH(K78,Assumptions!$A$23:$A$25,0)) -> 909095.51 | Q78: =J78*INDEX(Assumptions!$N$23:$N$25,MATCH(K78,Assumptions!$A$23:$A$25,0)) -> 176819.1 | R78: Metro club in Roodepoort. One Play bay. | T78: https://www.virginactive.co.za/gyms/roodepoort
A79: 75 | B79: Horizon View | C79: Gauteng | D79: Roodepoort | E79: Club | F79: 3 | G79: =INDEX(Rollout!$C$7:$C$9,F79) -> 2029 | H79: H1 2029 | I79: 5 | J79: 1 | K79: Play | L79: =INDEX(Assumptions!$B$23:$B$25,MATCH(K79,Assumptions!$A$23:$A$25,0)) -> Golfzon Vision Standard | M79: =J79*INDEX(Assumptions!$D$23:$D$25,MATCH(K79,Assumptions!$A$23:$A$25,0)) -> 841750 | N79: =J79*INDEX(Assumptions!$G$23:$G$25,MATCH(K79,Assumptions!$A$23:$A$25,0)) -> 1782 | O79: =J79*INDEX(Assumptions!$H$23:$H$25,MATCH(K79,Assumptions!$A$23:$A$25,0)) -> 641520 | P79: =J79*INDEX(Assumptions!$M$23:$M$25,MATCH(K79,Assumptions!$A$23:$A$25,0)) -> 909095.51 | Q79: =J79*INDEX(Assumptions!$N$23:$N$25,MATCH(K79,Assumptions!$A$23:$A$25,0)) -> 176819.1 | R79: Metro club in Roodepoort. One Play bay. | T79: https://www.virginactive.co.za/gyms/horizon-view
A80: 76 | B80: Little Falls | C80: Gauteng | D80: Roodepoort | E80: Club | F80: 3 | G80: =INDEX(Rollout!$C$7:$C$9,F80) -> 2029 | H80: H1 2029 | I80: 6 | J80: 1 | K80: Play | L80: =INDEX(Assumptions!$B$23:$B$25,MATCH(K80,Assumptions!$A$23:$A$25,0)) -> Golfzon Vision Standard | M80: =J80*INDEX(Assumptions!$D$23:$D$25,MATCH(K80,Assumptions!$A$23:$A$25,0)) -> 841750 | N80: =J80*INDEX(Assumptions!$G$23:$G$25,MATCH(K80,Assumptions!$A$23:$A$25,0)) -> 1782 | O80: =J80*INDEX(Assumptions!$H$23:$H$25,MATCH(K80,Assumptions!$A$23:$A$25,0)) -> 641520 | P80: =J80*INDEX(Assumptions!$M$23:$M$25,MATCH(K80,Assumptions!$A$23:$A$25,0)) -> 909095.51 | Q80: =J80*INDEX(Assumptions!$N$23:$N$25,MATCH(K80,Assumptions!$A$23:$A$25,0)) -> 176819.1 | R80: Metro club in Roodepoort. One Play bay. | T80: https://www.virginactive.co.za/gyms/little-falls
A81: 77 | B81: Krugersdorp | C81: Gauteng | D81: West Rand | E81: Club | F81: 3 | G81: =INDEX(Rollout!$C$7:$C$9,F81) -> 2029 | H81: H1 2029 | I81: 7 | J81: 1 | K81: Play | L81: =INDEX(Assumptions!$B$23:$B$25,MATCH(K81,Assumptions!$A$23:$A$25,0)) -> Golfzon Vision Standard | M81: =J81*INDEX(Assumptions!$D$23:$D$25,MATCH(K81,Assumptions!$A$23:$A$25,0)) -> 841750 | N81: =J81*INDEX(Assumptions!$G$23:$G$25,MATCH(K81,Assumptions!$A$23:$A$25,0)) -> 1782 | O81: =J81*INDEX(Assumptions!$H$23:$H$25,MATCH(K81,Assumptions!$A$23:$A$25,0)) -> 641520 | P81: =J81*INDEX(Assumptions!$M$23:$M$25,MATCH(K81,Assumptions!$A$23:$A$25,0)) -> 909095.51 | Q81: =J81*INDEX(Assumptions!$N$23:$N$25,MATCH(K81,Assumptions!$A$23:$A$25,0)) -> 176819.1 | R81: Metro club in West Rand. One Play bay. | T81: https://www.virginactive.co.za/gyms/krugersdorp
A82: 78 | B82: Eastgate | C82: Gauteng | D82: East Rand | E82: Club | F82: 3 | G82: =INDEX(Rollout!$C$7:$C$9,F82) -> 2029 | H82: H1 2029 | I82: 8 | J82: 1 | K82: Play | L82: =INDEX(Assumptions!$B$23:$B$25,MATCH(K82,Assumptions!$A$23:$A$25,0)) -> Golfzon Vision Standard | M82: =J82*INDEX(Assumptions!$D$23:$D$25,MATCH(K82,Assumptions!$A$23:$A$25,0)) -> 841750 | N82: =J82*INDEX(Assumptions!$G$23:$G$25,MATCH(K82,Assumptions!$A$23:$A$25,0)) -> 1782 | O82: =J82*INDEX(Assumptions!$H$23:$H$25,MATCH(K82,Assumptions!$A$23:$A$25,0)) -> 641520 | P82: =J82*INDEX(Assumptions!$M$23:$M$25,MATCH(K82,Assumptions!$A$23:$A$25,0)) -> 909095.51 | Q82: =J82*INDEX(Assumptions!$N$23:$N$25,MATCH(K82,Assumptions!$A$23:$A$25,0)) -> 176819.1 | R82: Metro club in East Rand. One Play bay. | T82: https://www.virginactive.co.za/gyms/eastgate
A83: 79 | B83: Edenglen | C83: Gauteng | D83: East Rand | E83: Club | F83: 3 | G83: =INDEX(Rollout!$C$7:$C$9,F83) -> 2029 | H83: H1 2029 | I83: 9 | J83: 1 | K83: Play | L83: =INDEX(Assumptions!$B$23:$B$25,MATCH(K83,Assumptions!$A$23:$A$25,0)) -> Golfzon Vision Standard | M83: =J83*INDEX(Assumptions!$D$23:$D$25,MATCH(K83,Assumptions!$A$23:$A$25,0)) -> 841750 | N83: =J83*INDEX(Assumptions!$G$23:$G$25,MATCH(K83,Assumptions!$A$23:$A$25,0)) -> 1782 | O83: =J83*INDEX(Assumptions!$H$23:$H$25,MATCH(K83,Assumptions!$A$23:$A$25,0)) -> 641520 | P83: =J83*INDEX(Assumptions!$M$23:$M$25,MATCH(K83,Assumptions!$A$23:$A$25,0)) -> 909095.51 | Q83: =J83*INDEX(Assumptions!$N$23:$N$25,MATCH(K83,Assumptions!$A$23:$A$25,0)) -> 176819.1 | R83: Metro club in East Rand. One Play bay. | T83: https://www.virginactive.co.za/gyms/edenglen
A84: 80 | B84: Glen Acres | C84: Gauteng | D84: Kempton Park | E84: Club | F84: 3 | G84: =INDEX(Rollout!$C$7:$C$9,F84) -> 2029 | H84: H1 2029 | I84: 10 | J84: 1 | K84: Play | L84: =INDEX(Assumptions!$B$23:$B$25,MATCH(K84,Assumptions!$A$23:$A$25,0)) -> Golfzon Vision Standard | M84: =J84*INDEX(Assumptions!$D$23:$D$25,MATCH(K84,Assumptions!$A$23:$A$25,0)) -> 841750 | N84: =J84*INDEX(Assumptions!$G$23:$G$25,MATCH(K84,Assumptions!$A$23:$A$25,0)) -> 1782 | O84: =J84*INDEX(Assumptions!$H$23:$H$25,MATCH(K84,Assumptions!$A$23:$A$25,0)) -> 641520 | P84: =J84*INDEX(Assumptions!$M$23:$M$25,MATCH(K84,Assumptions!$A$23:$A$25,0)) -> 909095.51 | Q84: =J84*INDEX(Assumptions!$N$23:$N$25,MATCH(K84,Assumptions!$A$23:$A$25,0)) -> 176819.1 | R84: Metro club in Kempton Park. One Play bay. | T84: https://www.virginactive.co.za/gyms/glen-acres
A85: 81 | B85: Sunward Park | C85: Gauteng | D85: Boksburg | E85: Club | F85: 3 | G85: =INDEX(Rollout!$C$7:$C$9,F85) -> 2029 | H85: H1 2029 | I85: 11 | J85: 1 | K85: Play | L85: =INDEX(Assumptions!$B$23:$B$25,MATCH(K85,Assumptions!$A$23:$A$25,0)) -> Golfzon Vision Standard | M85: =J85*INDEX(Assumptions!$D$23:$D$25,MATCH(K85,Assumptions!$A$23:$A$25,0)) -> 841750 | N85: =J85*INDEX(Assumptions!$G$23:$G$25,MATCH(K85,Assumptions!$A$23:$A$25,0)) -> 1782 | O85: =J85*INDEX(Assumptions!$H$23:$H$25,MATCH(K85,Assumptions!$A$23:$A$25,0)) -> 641520 | P85: =J85*INDEX(Assumptions!$M$23:$M$25,MATCH(K85,Assumptions!$A$23:$A$25,0)) -> 909095.51 | Q85: =J85*INDEX(Assumptions!$N$23:$N$25,MATCH(K85,Assumptions!$A$23:$A$25,0)) -> 176819.1 | R85: Metro club in Boksburg. One Play bay. | T85: https://www.virginactive.co.za/gyms/sunward-park
A86: 82 | B86: New Market | C86: Gauteng | D86: Alberton | E86: Club | F86: 3 | G86: =INDEX(Rollout!$C$7:$C$9,F86) -> 2029 | H86: H1 2029 | I86: 12 | J86: 1 | K86: Play | L86: =INDEX(Assumptions!$B$23:$B$25,MATCH(K86,Assumptions!$A$23:$A$25,0)) -> Golfzon Vision Standard | M86: =J86*INDEX(Assumptions!$D$23:$D$25,MATCH(K86,Assumptions!$A$23:$A$25,0)) -> 841750 | N86: =J86*INDEX(Assumptions!$G$23:$G$25,MATCH(K86,Assumptions!$A$23:$A$25,0)) -> 1782 | O86: =J86*INDEX(Assumptions!$H$23:$H$25,MATCH(K86,Assumptions!$A$23:$A$25,0)) -> 641520 | P86: =J86*INDEX(Assumptions!$M$23:$M$25,MATCH(K86,Assumptions!$A$23:$A$25,0)) -> 909095.51 | Q86: =J86*INDEX(Assumptions!$N$23:$N$25,MATCH(K86,Assumptions!$A$23:$A$25,0)) -> 176819.1 | R86: Metro club in Alberton. One Play bay. | T86: https://www.virginactive.co.za/gyms/new-market
...
